Workbook

Sheet Sheet1
R1: 'kkys; iks"k.k ;kstuk lu ¼2025& 2026½ | AE1: vkWDVkcj 2025
Q2: 'kkGsps uko &% bafnjkckbZ dU;k fo|ky; f'kjkGk -rk- ft- vejkorh | JT2: 2026 pk lkBk f'kYyd oxZ 5 oh rs 8 oh
C3: pkyq iVla[;k | I3: 'kk- iks- vkgkj fooj.k ,fizy 2026 | Q3: oxZ 5 oh ¼rkanqG½ | AB3: oxZ 6 oh rs 8 oh ¼rkanqG½ | AM3: oxZ 5 oh ¼gjcjk½ | AX3: oxZ 6 rs 8 oh ¼gjcjk½ | BI3: oxZ 5 oh ¼elqj MkG½ | BT3: oxZ 6 oh rs 8 oh ¼elqj MkG½ | CE3: oxZ 5 oh ¼ eVdh½ poGh | CP3: oxZ 6 oh rs 8 oh ¼eVdh½ poGh | DA3: oxZ 5 oh ¼eksgjh½ | DL3: oxZ 6 oh rs 8 oh ¼eksgjh½ | DW3: oxZ 5 oh ¼gGn½ | EH3: oxZ 6 oh rs 8 oh ¼gGn½ | ES3: oxZ 5 oh ¼dkank elkyk½ | FD3: oxZ 6 oh rs 8 oh ¼dkank elkyk½ | FO3: oxZ 5 oh ¼feB½ | FZ3: oxZ 6 oh rs 8 oh ¼feB½ | GK3: oxZ 5 oh ¼rsy½ | GV3: oxZ 6 oh rs 8 oh ¼rsy½ | HG3: oxZ 5 oh iqjd vkgkj | HS3: oxZ 6 oh rs 8 oh iqjd vkgkj | IQ3: 5 to | JK3: 6 To 8 | JT3: xks"kokjk
A4: okj | B4: fnukad | C4: oxZ 5 ok | D4: ,dq.k 5 ok | E4: 6 ok | F4: 7 ok | G4: 8 ok | H4: ,dq.k 6 rs 8 | I4: okj | J4: fnukad | K4: oxZ 5 oh | L4: oxZ 6 oh | M4: ,dq.k | N4: rif'ky | Q4: v- dz- | R4: efguk | S4: ekxhy f'kYyd | T4: iqjoBk/kkjd izkIr | U4: ,dq.k | V4: fo|kF;hZ la[;k | W4: izfr fo|kF;hz xzWe | X4: f'kto.;kr vkysyk rkanqG | Y4: fnol v[ksj f'kYyd rkanqG | Z4: fuOoG f'kYyd rkanqG | AA4: v- dz- | AB4: efguk | AC4: ekxhy f'kYyd | AD4: iqjoBk/kkjd izkIr | AE4: ,dq.k | AF4: fo|kF;hZ la[;k | AG4: izfr fo|kF;hz xzWe | AH4: f'kto.;kr vkysyk rkanqG | AI4: efgukc[ksj f'kYyd rkanqG | AJ4: fuOoG f'kYyd rkanqG | AK4: oxZ 5 oh rs 8 oh rkanqG f'kYyd | AM4: v- dz- | AN4: efguk | AO4: ekxhy f'kYyd | AP4: iqjoBk/kkjd izkIr | AQ4: ,dq.k | AR4: fo|kF;hZ la[;k | AS4: izfr fo|kF;hz xzWe | AT4: f'kto.;kr vkysyk okVk.kk | AU4: fnol v[ksj f'kYyd okVk.kk | AV4: fuOoG f'kYyd okVk.kk | AW4: v- dz- | AX4: efguk | AY4: ekxhy f'kYyd | AZ4: iqjoBk/kkjd izkIr | BA4: ,dq.k | BB4: fo|kF;hZ la[;k | BC4: izfr fo|kF;hz xzWe | BD4: f'kto.;kr vkysyk okVk.kk | BE4: efgukc[ksj f'kYyd okVk.kk | BF4: fuOoG f'kYyd okVk.kk | BG4: oxZ 5 oh rs 8 oh okVk.kk f'kYyd | BI4: v- dz- | BJ4: efguk | BK4: ekxhy f'kYyd | BL4: iqjoBk/kkjd izkIr | BM4: ,dq.k | BN4: fo|kF;hZ la[;k | BO4: izfr fo|kF;hz xzWe | BP4: f'kto.;kr vkysyk elqj MkG | BQ4: fnol v[ksj f'kYyd elqj MkG | BR4: fuOoG f'kYyd elqj MkG | BS4: v- dz- | BT4: efguk | BU4: ekxhy f'kYyd | BV4: iqjoBk/kkjd izkIr | BW4: ,dq.k | BX4: fo|kF;hZ la[;k | BY4: izfr fo|kF;hz xzWe | BZ4: f'kto.;kr vkysyk elqj MkG | CA4: efgukc[ksj f'kYyd elqj MkG | CB4: fuOoG f'kYyd elqj MkG | CC4: oxZ 5 oh rs 8 oh elqj MkG f'kYyd | CE4: v- dz- | CF4: efguk | CG4: ekxhy f'kYyd | CH4: iqjoBk/kkjd izkIr | CI4: ,dq.k | CJ4: fo|kF;hZ la[;k | CK4: izfr fo|kF;hz xzWe | CL4: f'kto.;kr vkysyk gjcjk | CM4: fnol v[ksj f'kYyd gjcjk | CN4: fuOoG f'kYyd gjcjk | CO4: v- dz- | CP4: efguk | CQ4: ekxhy f'kYyd | CR4: iqjoBk/kkjd izkIr | CS4: ,dq.k | CT4: fo|kF;hZ la[;k | CU4: izfr fo|kF;hz xzWe | CV4: f'kto.;kr vkysyk gjcjk | CW4: efgukc[ksj f'kYyd gjcjk | CX4: fuOoG f'kYyd gjcjk | CY4: oxZ 5 oh rs 8 oh gjcjk f'kYyd | DA4: v- dz- | DB4: efguk | DC4: ekxhy f'kYyd | DD4: iqjoBk/kkjd izkIr | DE4: ,dq.k | DF4: fo|kF;hZ la[;k | DG4: izfr fo|kF;hz xzWe | DH4: f'kto.;kr vkysyk eksgjh | DI4: fnol v[ksj f'kYyd eksgjh | DJ4: fuOoG f'kYyd eksgjh | DK4: v- dz- | DL4: efguk | DM4: ekxhy f'kYyd | DN4: iqjoBk/kkjd izkIr | DO4: ,dq.k | DP4: fo|kF;hZ la[;k | DQ4: izfr fo|kF;hz xzWe | DR4: f'kto.;kr vkysyk eksgjh | DS4: efgukc[ksj f'kYyd eksgjh | DT4: fuOoG f'kYyd eksgjh | DU4: oxZ 5 oh rs 8 oh eksgjh f'kYyd | DW4: v- dz- | DX4: efguk | DY4: ekxhy f'kYyd | DZ4: iqjoBk/kkjd izkIr | EA4: ,dq.k | EB4: fo|kF;hZ la[;k | EC4: izfr fo|kF;hz xzWe | ED4: f'kto.;kr vkysyk gGn | EE4: fnol v[ksj f'kYyd gGn | EF4: fuOoG f'kYyd gGn | EG4: v- dz- | EH4: efguk | EI4: ekxhy f'kYyd | EJ4: iqjoBk/kkjd izkIr | EK4: ,dq.k | EL4: fo|kF;hZ la[;k | EM4: izfr fo|kF;hz xzWe | EN4: f'kto.;kr vkysyk gGn | EO4: efgukc[ksj f'kYyd gGn | EP4: fuOoG f'kYyd gGn | EQ4: oxZ 5 oh rs 8 oh gGn f'kYyd | ES4: v- dz- | ET4: efguk | EU4: ekxhy f'kYyd | EV4: iqjoBk/kkjd izkIr | EW4: ,dq.k | EX4: fo|kF;hZ la[;k | EY4: izfr fo|kF;hz xzWe | EZ4: f'kto.;kr vkysyk dkank elkyk | FA4: fnol v[ksj f'kYyd dkank elkyk | FB4: fuOoG f'kYyd dkank elkyk | FC4: v- dz- | FD4: efguk | FE4: ekxhy f'kYyd | FF4: iqjoBk/kkjd izkIr | FG4: ,dq.k | FH4: fo|kF;hZ la[;k | FI4: izfr fo|kF;hz xzWe | FJ4: f'kto.;kr vkysyk dkank elkyk | FK4: fnol v[ksj f'kYyd dkank elkyk | FL4: fuOoG f'kYyd dkank elkyk | FM4: oxZ 5 oh rs 8 oh dkank elkyk f'kYyd | FO4: v- dz- | FP4: efguk | FQ4: ekxhy f'kYyd | FR4: iqjoBk/kkjd izkIr | FS4: ,dq.k | FT4: fo|kF;hZ la[;k | FU4: izfr fo|kF;hz xzWe | FV4: f'kto.;kr vkysyk feB | FW4: fnol v[ksj f'kYyd feB | FX4: fuOoG f'kYyd feB | FY4: v- dz- | FZ4: efguk | GA4: ekxhy f'kYyd | GB4: iqjoBk/kkjd izkIr | GC4: ,dq.k | GD4: fo|kF;hZ la[;k | GE4: izfr fo|kF;hz xzWe | GF4: f'kto.;kr vkysyk feB | GG4: fnol v[ksj f'kYyd feB | GH4: fuOoG f'kYyd feB | GI4: oxZ 5 oh rs 8 oh feB f'kYyd | GK4: v- dz- | GL4: efguk | GM4: ekxhy f'kYyd | GN4: iqjoBk/kkjd izkIr | GO4: ,dq.k | GP4: fo|kF;hZ la[;k | GQ4: izfr fo|kF;hz 5 xzWe | GR4: f'kto.;kr vkysyk rsy | GS4: fnol v[ksj f'kYyd rsy | GT4: fuOoG f'kYyd rsy | GU4: v- dz- | GV4: efguk | GW4: ekxhy f'kYyd | GX4: iqjoBk/kkjd izkIr | GY4: ,dq.k | GZ4: fo|kF;hZ la[;k | HA4: izfr fo|kF;hz 7.5 xzWe | HB4: f'kto.;kr vkysyk rsy | HC4: fnol v[ksj f'kYyd rsy | HD4: fuOoG f'kYyd rsy | HE4: oxZ 5 oh rs 8 oh rsy f'kYyd | HG4: v- dz- | HH4: efguk | HI4: fo|kF;hZ la[;k | HJ4: Hkkftikyk [kpZ nj ¼ 0.79½ | HK4: Hkkftikyk [kpZ jDde | HL4: ba/ku [kpZ nj ¼ 0.71½ | HM4: ba/ku [kpZ jDde | HN4: iqjd vkgkj [kpZ nj ¼ 0.58½ | HO4: iqjd vkgkj [kpZ jDde | HP4: ,dq.k [kpZ nj ¼ 2.08½ | HQ4: ,dq.k [kpZ jDde | HR4: v- dz- | HS4: efguk | HT4: fo|kF;hZ la[;k | HU4: Hkkftikyk [kpZ nj ¼1.25½ | HV4: Hkkftikyk [kpZ jDde | HW4: ba/ku [kpZ nj ¼ 0.96½ | HX4: ba/ku [kpZ jDde | HY4: iqjd vkgkj [kpZ nj ¼ 0.90½ | HZ4: iqjd vkgkj [kpZ jDde | IA4: ,dq.k [kpZ nj ¼ 3.11½ | IB4: ,dq.k [kpZ jDde | IC4: oxZ 5 oh rs 8 oh Hkkftikyk [kpZ | ID4: oxZ 5 oh rs 8 oh ba/ku [kpZ | IE4: oxZ 5 oh rs 8 oh iqjd vkgkj [kpZ | IG4: fnukad | IH4: okj | II4: rif'ky | IJ4: pkyq efg.;kph iVla[;k | IK4: nSfud mifLFkrh@yHkkF;hZ | IL4: izR;{k ykHkkF;hZ @ rkVkaph la[;k | IM4: rkanqG | IN4: elwjnkG | IO4: okVk.kk | IP4: gjHkjk | IQ4: eksgjh | IR4: gGn | IS4: fejph ikoMj | IT4: lks;kchu rsy | IU4: feB | IV4: Hkkftikyk | IW4: iqjd vkgkj | IX4: ykHkkFkhZ uqlkj gks.kjk [kpZ | IZ4: fnukad | JA4: okj | JB4: rif'ky | JC4: pkyq efg.;kph iVla[;k | JD4: nSfud mifLFkrh@yHkkF;hZ | JE4: izR;{k ykHkkF;hZ @ rkVkaph la[;k | JF4: rkanqG | JG4: elwjnkG | JH4: okVk.kk | JI4: gjHkjk | JJ4: eksgjh | JK4: gGn | JL4: fejph ikoMj | JM4: lks;kchu rsy | JN4: feB | JO4: Hkkftikyk | JP4: iqjd vkgkj | JQ4: ykHkkFkhZ uqlkj gks.kjk [kpZ | JT4: v- Ø- | JU4: oLrqps uko | JV4: ¼oxZ 5 ok ½ ekfxy f'kYyd oLrw ¼fd- xzW-½ | JW4: ¼oxZ 6 oh rs 8 oh ½ ekfxy f'kYyd oLrw ¼fd- xzW-½ | JX4: ,dq.k lkBk f'kYyd ¼ 5 oh oh rs 8 oh ½ | JY4: 'ksjk | KA4: v- Ø- | KB4: oLrqps uko | KC4: ¼oxZ 5 ok ½ ekfxy f'kYyd oLrw ¼fd- xzW-½ | KD4: izkIr lkfgR; | KE4: [kpZ rknqG | KF4: fo|kF;hZ la[;k | KG4: ¼oxZ 6 oh rs 8 oh ½ ekfxy f'kYyd oLrw ¼fd- xzW-½ | KH4: izkIr lkfgR; | KI4: [kpZ rknqG | KJ4: fo|kF;hZ la[;k
A5: cq/kokj | B5: 01/04/2026 | C5: 40 | D5: =C5 | E5: 12 | F5: 14 | G5: 10 | H5: =G5+F5+E5 | I5: cq/kokj | J5: 01/04/2026 | K5: =D5 | L5: =H5 | M5: =SUM(K5:L5) | N5: eVdh | Q5: 1 | R5: 01/04/2026 | S5: 135.8 | T5: 0 | U5: =S5+T5 | V5: =K5 | W5: 0.1 | X5: =V5*W5 | Y5: =U5-X5 | Z5: =Y5 | AA5: 1 | AB5: =R5 | AC5: 382 | AD5: 0 | AE5: =AC5+AD5 | AF5: =L5 | AG5: 0.15 | AH5: =AG5*AF5 | AI5: =AE5-AH5 | AJ5: =AI5 | AK5: =Z5+AJ5 | AM5: 1 | AN5: =AB5 | AO5: 18.18 | AP5: 0 | AQ5: =AO5+AP5 | AR5: 0 | AS5: 0.02 | AT5: =AR5*AS5 | AU5: =AQ5-AT5 | AV5: =AU5 | AW5: 1 | AX5: =AN5 | AY5: 33.48 | AZ5: 0 | BA5: =AY5+AZ5 | BB5: 0 | BC5: 0.03 | BD5: =BC5*BB5 | BE5: =BA5-BD5 | BF5: =BE5 | BG5: =AV5+BF5 | BI5: 1 | BJ5: =AX5 | BK5: 17.54 | BL5: 0 | BM5: =BK5+BL5 | BN5: 0 | BO5: 0.02 | BP5: =BN5*BO5 | BQ5: =BM5-BP5 | BR5: =BQ5 | BS5: 1 | BT5: =BJ5 | BU5: 33.51 | BV5: 0 | BW5: =BU5+BV5 | BX5: 0 | BY5: 0.03 | BZ5: =BY5*BX5 | CA5: =BW5-BZ5 | CB5: =CA5 | CC5: =BR5+CB5 | CE5: 1 | CF5: =BT5 | CG5: 18.36 | CH5: 0 | CI5: =CG5+CH5 | CJ5: =K5 | CK5: 0.02 | CL5: =CJ5*CK5 | CM5: =CI5-CL5 | CN5: =CM5 | CO5: 1 | CP5: =CF5 | CQ5: 32.62 | CR5: 0 | CS5: =CQ5+CR5 | CT5: =L5 | CU5: 0.03 | CV5: =CU5*CT5 | CW5: =CS5-CV5 | CX5: =CW5 | CY5: =CN5+CX5 | DA5: 1 | DB5: =CP5 | DC5: 0.631 | DD5: 0 | DE5: =DC5+DD5 | DF5: =K5 | DG5: 0.0001 | DH5: =DF5*DG5 | DI5: =DE5-DH5 | DJ5: =DI5 | DK5: 1 | DL5: =DB5 | DM5: 1.324 | DN5: 0 | DO5: =DM5+DN5 | DP5: =L5 | DQ5: 0.0003 | DR5: =DQ5*DP5 | DS5: =DO5-DR5 | DT5: =DS5 | DU5: =DJ5+DT5 | DW5: 1 | DX5: =DL5 | DY5: 0.933 | DZ5: 0 | EA5: =DY5+DZ5 | EB5: =K5 | EC5: 0.0002 | ED5: =EB5*EC5 | EE5: =EA5-ED5 | EF5: =EE5 | EG5: 1 | EH5: =DX5 | EI5: 2.128 | EJ5: 0 | EK5: =EI5+EJ5 | EL5: =L5 | EM5: 0.0006 | EN5: =EM5*EL5 | EO5: =EK5-EN5 | EP5: =EO5 | EQ5: =EF5+EP5 | ES5: 1 | ET5: =EH5 | EU5: 2.293 | EV5: 0 | EW5: =EU5+EV5 | EX5: =K5 | EY5: 0.002 | EZ5: =EX5*EY5 | FA5: =EW5-EZ5 | FB5: =FA5 | FC5: 1 | FD5: =ET5 | FE5: 8.496 | FF5: 0 | FG5: =FE5+FF5 | FH5: =L5 | FI5: 0.0025 | FJ5: =FI5*FH5 | FK5: =FG5-FJ5 | FL5: =FK5 | FM5: =FB5+FL5 | FO5: 1 | FP5: =FD5 | FQ5: 3.437 | FR5: 0 | FS5: =FQ5+FR5 | FT5: =K5 | FU5: 0.002 | FV5: =FT5*FU5 | FW5: =FS5-FV5 | FX5: =FW5 | FY5: 1 | FZ5: =FP5 | GA5: 14.493 | GB5: 0 | GC5: =GA5+GB5 | GD5: =L5 | GE5: 0.005 | GF5: =GE5*GD5 | GG5: =GC5-GF5 | GH5: =GG5 | GI5: =FX5+GH5 | GK5: 1 | GL5: =FZ5 | GM5: 4.438 | GN5: 0 | GO5: =GM5+GN5 | GP5: =K5 | GQ5: 0.005 | GR5: =GP5*GQ5 | GS5: =GO5-GR5 | GT5: =GS5 | GU5: 1 | GV5: =GL5 | GW5: 21.552 | GX5: 0 | GY5: =GW5+GX5 | GZ5: =L5 | HA5: 0.0075 | HB5: =HA5*GZ5 | HC5: =GY5-HB5 | HD5: =HC5 | HE5: =GT5+HD5 | HG5: 1 | HH5: =GV5 | HI5: =K5 | HJ5: 1 | HK5: =HI5*HJ5 | HL5: 0.89 | HM5: =HI5*HL5 | HN5: 0.7 | HO5: =HN5*HI5 | HP5: 2.59 | HQ5: =HI5*HP5 | HR5: 1 | HS5: 44933 | HT5: =L5 | HU5: 1.64 | HV5: =HT5*HU5 | HW5: 1.14 | HX5: =HT5*HW5 | HY5: 1.1 | HZ5: =HY5*HT5 | IA5: 3.88 | IB5: =HT5*IA5 | IC5: =HK5+HV5 | ID5: =HM5+HX5 | IE5: =HO5+HZ5 | IG5: =HH5 | IH5: xq:okj | II5: elqj nkG | IJ5: =C5 | IK5: =IJ5 | IL5: =K5 | IM5: =IL5*100 | IN5: =IL5*20 | IQ5: =IL5*0.3 | IR5: =IL5*0.4 | IS5: =IL5*1.5 | IT5: =IL5*5 | IU5: =IL5*2 | IV5: =IL5*2.08 | IX5: =IL5*2.08 | IZ5: =IG5 | JA5: xq:okj | JB5: elqj nkG | JC5: 45 | JD5: =JC5 | JE5: =L5 | JF5: =JE5*150 | JG5: =JE5*30 | JJ5: =JE5*0.25 | JK5: =JE5*0.4 | JL5: =JE5*2.5 | JM5: =JE5*7.5 | JN5: =JE5*4 | JO5: =JE5*3.11 | JQ5: =JE5*3.11 | JT5: 1 | JU5: 2 | JV5: 3 | JW5: 4 | JX5: 5 | JY5: 6 | KA5: 1 | KB5: 2 | KC5: 3 | KD5: 4 | KE5: 5 | KF5: 6 | KG5: 1 | KH5: 2 | KI5: 3 | KJ5: 4
A6: xq:okj | B6: 02/04/2026 | C6: 0 | D6: =C6 | E6: 0 | F6: 0 | G6: 0 | H6: =G6+F6+E6 | I6: xq:okj | J6: 02/04/2026 | K6: =D6 | L6: =H6 | M6: =SUM(K6:L6) | N6: elqj nkG | Q6: 2 | R6: 02/04/2026 | S6: =Z5 | T6: 0 | U6: =S6+T6 | V6: =K6 | W6: 0.1 | X6: =V6*W6 | Y6: =U6-X6 | Z6: =Y6 | AA6: 2 | AB6: =R6 | AC6: =AJ5 | AD6: 0 | AE6: =AC6+AD6 | AF6: =L6 | AG6: 0.15 | AH6: =AG6*AF6 | AI6: =AE6-AH6 | AJ6: =AI6 | AK6: =Z6+AJ6 | AM6: 2 | AN6: =AB6 | AO6: =AV5 | AP6: 0 | AQ6: =AO6+AP6 | AR6: 0 | AS6: 0.02 | AT6: =AR6*AS6 | AU6: =AQ6-AT6 | AV6: =AU6 | AW6: 2 | AX6: =AN6 | AY6: =BF5 | AZ6: 0 | BA6: =AY6+AZ6 | BB6: 0 | BC6: 0.03 | BD6: =BC6*BB6 | BE6: =BA6-BD6 | BF6: =BE6 | BG6: =AV6+BF6 | BI6: 2 | BJ6: =AX6 | BK6: =BR5 | BL6: 0 | BM6: =BK6+BL6 | BN6: =K6 | BO6: 0.02 | BP6: =BN6*BO6 | BQ6: =BM6-BP6 | BR6: =BQ6 | BS6: 2 | BT6: =BJ6 | BU6: =CB5 | BV6: 0 | BW6: =BU6+BV6 | BX6: =L6 | BY6: 0.03 | BZ6: =BY6*BX6 | CA6: =BW6-BZ6 | CB6: =CA6 | CC6: =BR6+CB6 | CE6: 2 | CF6: =BT6 | CG6: =CN5 | CH6: 0 | CI6: =CG6+CH6 | CJ6: 0 | CK6: 0.02 | CL6: =CJ6*CK6 | CM6: =CI6-CL6 | CN6: =CM6 | CO6: 2 | CP6: =CF6 | CQ6: =CX5 | CR6: 0 | CS6: =CQ6+CR6 | CT6: 0 | CU6: 0.03 | CV6: =CU6*CT6 | CW6: =CS6-CV6 | CX6: =CW6 | CY6: =CN6+CX6 | DA6: 2 | DB6: =CP6 | DC6: =DJ5 | DD6: 0 | DE6: =DC6+DD6 | DF6: =K6 | DG6: 0.0001 | DH6: =DF6*DG6 | DI6: =DE6-DH6 | DJ6: =DI6 | DK6: 2 | DL6: =DB6 | DM6: =DT5 | DN6: 0 | DO6: =DM6+DN6 | DP6: =L6 | DQ6: 0.0003 | DR6: =DQ6*DP6 | DS6: =DO6-DR6 | DT6: =DS6 | DU6: =DJ6+DT6 | DW6: 2 | DX6: =DL6 | DY6: =EF5 | DZ6: 0 | EA6: =DY6+DZ6 | EB6: =K6 | EC6: 0.0002 | ED6: =EB6*EC6 | EE6: =EA6-ED6 | EF6: =EE6 | EG6: 2 | EH6: =DX6 | EI6: =EP5 | EJ6: 0 | EK6: =EI6+EJ6 | EL6: =L6 | EM6: 0.0006 | EN6: =EM6*EL6 | EO6: =EK6-EN6 | EP6: =EO6 | EQ6: =EF6+EP6 | ES6: 2 | ET6: =EH6 | EU6: =FB5 | EV6: 0 | EW6: =EU6+EV6 | EX6: =K6 | EY6: 0.002 | EZ6: =EX6*EY6 | FA6: =EW6-EZ6 | FB6: =FA6 | FC6: 2 | FD6: =ET6 | FE6: =FL5 | FF6: 0 | FG6: =FE6+FF6 | FH6: =L6 | FI6: 0.0025 | FJ6: =FI6*FH6 | FK6: =FG6-FJ6 | FL6: =FK6 | FM6: =FB6+FL6 | FO6: 2 | FP6: =FD6 | FQ6: =FX5 | FR6: 0 | FS6: =FQ6+FR6 | FT6: =K6 | FU6: 0.002 | FV6: =FT6*FU6 | FW6: =FS6-FV6 | FX6: =FW6 | FY6: 2 | FZ6: =FP6 | GA6: =GH5 | GB6: 0 | GC6: =GA6+GB6 | GD6: =L6 | GE6: 0.005 | GF6: =GE6*GD6 | GG6: =GC6-GF6 | GH6: =GG6 | GI6: =FX6+GH6 | GK6: 2 | GL6: =FZ6 | GM6: =GT5 | GN6: 0 | GO6: =GM6+GN6 | GP6: =K6 | GQ6: 0.005 | GR6: =GP6*GQ6 | GS6: =GO6-GR6 | GT6: =GS6 | GU6: 2 | GV6: =GL6 | GW6: =HD5 | GX6: 0 | GY6: =GW6+GX6 | GZ6: =L6 | HA6: 0.0075 | HB6: =HA6*GZ6 | HC6: =GY6-HB6 | HD6: =HC6 | HE6: =GT6+HD6 | HG6: 2 | HH6: =GV6 | HI6: =K6 | HJ6: 1 | HK6: =HI6*HJ6 | HL6: 0.89 | HM6: =HI6*HL6 | HN6: 0.7 | HO6: =HN6*HI6 | HP6: 2.59 | HQ6: =HI6*HP6 | HR6: 2 | HS6: 44964 | HT6: =L6 | HU6: 1.64 | HV6: =HT6*HU6 | HW6: 1.14 | HX6: =HT6*HW6 | HY6: 1.1 | HZ6: =HY6*HT6 | IA6: 3.11 | IB6: =HT6*IA6 | IC6: =HK6+HV6 | ID6: =HM6+HX6 | IE6: =HO6+HZ6 | IG6: =HH6 | IH6: 'kqdzokj | II6: okVk.kk | IJ6: =IJ5 | IK6: =IJ6 | IL6: =K6 | IM6: =IL6*100 | IO6: =IL6*20 | IQ6: =IL6*0.3 | IR6: =IL6*0.4 | IS6: =IL6*1.5 | IT6: =IL6*5 | IU6: =IL6*2 | IV6: =IL6*2.08 | IX6: =IL6*2.08 | IZ6: =IG6 | JA6: 'kqdzokj | JB6: okVk.kk | JC6: =JC5 | JD6: =JC6 | JE6: =L6 | JF6: =JE6*150 | JH6: =JE6*30 | JJ6: =JE6*0.25 | JK6: =JE6*0.4 | JL6: =JE6*2.5 | JM6: =JE6*7.5 | JN6: =JE6*4 | JO6: =JE6*3.11 | JQ6: =JE6*3.11 | JT6: 1 | JU6: rkanqG | JV6: =Z35 | JW6: =AJ35 | JX6: =SUM(JV6:JW6) | KA6: 1 | KB6: rkanqG | KC6: =JV6 | KD6: =T36 | KE6: =X36 | KF6: =V36 | KG6: =JW6 | KH6: =AD36 | KI6: =AH36 | KJ6: =AF36
A7: 'kqdzokj | B7: 03/04/2026 | C7: 0 | D7: =C7 | E7: 0 | F7: 0 | G7: 0 | H7: =G7+F7+E7 | I7: 'kqdzokj | J7: 03/04/2026 | K7: =D7 | L7: =H7 | M7: =SUM(K7:L7) | N7: poGh | Q7: 3 | R7: 03/04/2026 | S7: =Z6 | T7: 0 | U7: =S7+T7 | V7: =K7 | W7: 0.1 | X7: =V7*W7 | Y7: =U7-X7 | Z7: =Y7 | AA7: 3 | AB7: =R7 | AC7: =AJ6 | AD7: 0 | AE7: =AC7+AD7 | AF7: =L7 | AG7: 0.15 | AH7: =AG7*AF7 | AI7: =AE7-AH7 | AJ7: =AI7 | AK7: =Z7+AJ7 | AM7: 3 | AN7: =AB7 | AO7: =AV6 | AP7: 0 | AQ7: =AO7+AP7 | AR7: 0 | AS7: 0.02 | AT7: =AR7*AS7 | AU7: =AQ7-AT7 | AV7: =AU7 | AW7: 3 | AX7: =AN7 | AY7: =BF6 | AZ7: 0 | BA7: =AY7+AZ7 | BB7: 0 | BC7: 0.03 | BD7: =BC7*BB7 | BE7: =BA7-BD7 | BF7: =BE7 | BG7: =AV7+BF7 | BI7: 3 | BJ7: =AX7 | BK7: =BR6 | BL7: 0 | BM7: =BK7+BL7 | BN7: 0 | BO7: 0.02 | BP7: =BN7*BO7 | BQ7: =BM7-BP7 | BR7: =BQ7 | BS7: 3 | BT7: =BJ7 | BU7: =CB6 | BV7: 0 | BW7: =BU7+BV7 | BX7: 0 | BY7: 0.03 | BZ7: =BY7*BX7 | CA7: =BW7-BZ7 | CB7: =CA7 | CC7: =BR7+CB7 | CE7: 3 | CF7: =BT7 | CG7: =CN6 | CH7: 0 | CI7: =CG7+CH7 | CJ7: 0 | CK7: 0.02 | CL7: =CJ7*CK7 | CM7: =CI7-CL7 | CN7: =CM7 | CO7: 3 | CP7: =CF7 | CQ7: =CX6 | CR7: 0 | CS7: =CQ7+CR7 | CT7: 0 | CU7: 0.03 | CV7: =CU7*CT7 | CW7: =CS7-CV7 | CX7: =CW7 | CY7: =CN7+CX7 | DA7: 3 | DB7: =CP7 | DC7: =DJ6 | DD7: 0 | DE7: =DC7+DD7 | DF7: =K7 | DG7: 0.0001 | DH7: =DF7*DG7 | DI7: =DE7-DH7 | DJ7: =DI7 | DK7: 3 | DL7: =DB7 | DM7: =DT6 | DN7: 0 | DO7: =DM7+DN7 | DP7: =L7 | DQ7: 0.0003 | DR7: =DQ7*DP7 | DS7: =DO7-DR7 | DT7: =DS7 | DU7: =DJ7+DT7 | DW7: 3 | DX7: =DL7 | DY7: =EF6 | DZ7: 0 | EA7: =DY7+DZ7 | EB7: =K7 | EC7: 0.0002 | ED7: =EB7*EC7 | EE7: =EA7-ED7 | EF7: =EE7 | EG7: 3 | EH7: =DX7 | EI7: =EP6 | EJ7: 0 | EK7: =EI7+EJ7 | EL7: =L7 | EM7: 0.0006 | EN7: =EM7*EL7 | EO7: =EK7-EN7 | EP7: =EO7 | EQ7: =EF7+EP7 | ES7: 3 | ET7: =EH7 | EU7: =FB6 | EV7: 0 | EW7: =EU7+EV7 | EX7: =K7 | EY7: 0.002 | EZ7: =EX7*EY7 | FA7: =EW7-EZ7 | FB7: =FA7 | FC7: 3 | FD7: =ET7 | FE7: =FL6 | FF7: 0 | FG7: =FE7+FF7 | FH7: =L7 | FI7: 0.0025 | FJ7: =FI7*FH7 | FK7: =FG7-FJ7 | FL7: =FK7 | FM7: =FB7+FL7 | FO7: 3 | FP7: =FD7 | FQ7: =FX6 | FR7: 0 | FS7: =FQ7+FR7 | FT7: =K7 | FU7: 0.002 | FV7: =FT7*FU7 | FW7: =FS7-FV7 | FX7: =FW7 | FY7: 3 | FZ7: =FP7 | GA7: =GH6 | GB7: 0 | GC7: =GA7+GB7 | GD7: =L7 | GE7: 0.005 | GF7: =GE7*GD7 | GG7: =GC7-GF7 | GH7: =GG7 | GI7: =FX7+GH7 | GK7: 3 | GL7: =FZ7 | GM7: =GT6 | GN7: 0 | GO7: =GM7+GN7 | GP7: =K7 | GQ7: 0.005 | GR7: =GP7*GQ7 | GS7: =GO7-GR7 | GT7: =GS7 | GU7: 3 | GV7: =GL7 | GW7: =HD6 | GX7: 0 | GY7: =GW7+GX7 | GZ7: =L7 | HA7: 0.0075 | HB7: =HA7*GZ7 | HC7: =GY7-HB7 | HD7: =HC7 | HE7: =GT7+HD7 | HG7: 3 | HH7: =GV7 | HI7: =K7 | HJ7: 1 | HK7: =HI7*HJ7 | HL7: 0.89 | HM7: =HI7*HL7 | HN7: 0.7 | HO7: =HN7*HI7 | HP7: 2.59 | HQ7: =HI7*HP7 | HR7: 3 | HS7: 44992 | HT7: =L7 | HU7: 1.64 | HV7: =HT7*HU7 | HW7: 1.14 | HX7: =HT7*HW7 | HY7: 1.1 | HZ7: =HY7*HT7 | IA7: 3.11 | IB7: =HT7*IA7 | IC7: =HK7+HV7 | ID7: =HM7+HX7 | IE7: =HO7+HZ7 | IG7: =HH7 | IH7: 'kfuokj | II7: gjcjk | IJ7: =IJ6 | IK7: =IJ7 | IL7: =K7 | IM7: =IL7*100 | IP7: =IL7*20 | IQ7: =IL7*0.3 | IR7: =IL7*0.4 | IS7: =IL7*1.5 | IT7: =IL7*5 | IU7: =IL7*2 | IV7: =IL7*2.08 | IX7: =IL7*2.08 | IZ7: =IG7 | JA7: 'kfuokj | JB7: gjcjk | JC7: =JC6 | JD7: =JC7 | JE7: =L7 | JF7: =JE7*150 | JI7: =JE7*30 | JJ7: =JE7*0.25 | JK7: =JE7*0.4 | JL7: =JE7*2.5 | JM7: =JE7*7.5 | JN7: =JE7*4 | JO7: =JE7*3.11 | JQ7: =JE7*3.11 | JT7: 2 | KA7: 2 | KB7: eqxnkG | KC7: =JV7 | KD7: 0 | KE7: 0 | KF7: 0 | KG7: =JW7 | KH7: 0 | KI7: 0 | KJ7: 0
A8: 'kfuokj | B8: 04/04/2026 | C8: 0 | D8: =C8 | E8: 0 | F8: 0 | G8: 0 | H8: =G8+F8+E8 | I8: 'kfuokj | J8: 04/04/2026 | K8: =D8 | L8: =H8 | M8: =SUM(K8:L8) | N8: gjcjk | Q8: 4 | R8: 04/04/2026 | S8: =Z7 | T8: 0 | U8: =S8+T8 | V8: =K8 | W8: 0.1 | X8: =V8*W8 | Y8: =U8-X8 | Z8: =Y8 | AA8: 4 | AB8: =R8 | AC8: =AJ7 | AD8: 0 | AE8: =AC8+AD8 | AF8: =L8 | AG8: 0.15 | AH8: =AG8*AF8 | AI8: =AE8-AH8 | AJ8: =AI8 | AK8: =Z8+AJ8 | AM8: 4 | AN8: =AB8 | AO8: =AV7 | AP8: 0 | AQ8: =AO8+AP8 | AR8: =K8 | AS8: 0.02 | AT8: =AR8*AS8 | AU8: =AQ8-AT8 | AV8: =AU8 | AW8: 4 | AX8: =AN8 | AY8: =BF7 | AZ8: 0 | BA8: =AY8+AZ8 | BB8: =L8 | BC8: 0.03 | BD8: =BC8*BB8 | BE8: =BA8-BD8 | BF8: =BE8 | BG8: =AV8+BF8 | BI8: 4 | BJ8: =AX8 | BK8: =BR7 | BL8: 0 | BM8: =BK8+BL8 | BN8: 0 | BO8: 0.02 | BP8: =BN8*BO8 | BQ8: =BM8-BP8 | BR8: =BQ8 | BS8: 4 | BT8: =BJ8 | BU8: =CB7 | BV8: 0 | BW8: =BU8+BV8 | BX8: 0 | BY8: 0.03 | BZ8: =BY8*BX8 | CA8: =BW8-BZ8 | CB8: =CA8 | CC8: =BR8+CB8 | CE8: 4 | CF8: =BT8 | CG8: =CN7 | CH8: 0 | CI8: =CG8+CH8 | CJ8: 0 | CK8: 0.02 | CL8: =CJ8*CK8 | CM8: =CI8-CL8 | CN8: =CM8 | CO8: 4 | CP8: =CF8 | CQ8: =CX7 | CR8: 0 | CS8: =CQ8+CR8 | CT8: 0 | CU8: 0.03 | CV8: =CU8*CT8 | CW8: =CS8-CV8 | CX8: =CW8 | CY8: =CN8+CX8 | DA8: 4 | DB8: =CP8 | DC8: =DJ7 | DD8: 0 | DE8: =DC8+DD8 | DF8: =K8 | DG8: 0.0001 | DH8: =DF8*DG8 | DI8: =DE8-DH8 | DJ8: =DI8 | DK8: 4 | DL8: =DB8 | DM8: =DT7 | DN8: 0 | DO8: =DM8+DN8 | DP8: =L8 | DQ8: 0.0003 | DR8: =DQ8*DP8 | DS8: =DO8-DR8 | DT8: =DS8 | DU8: =DJ8+DT8 | DW8: 4 | DX8: =DL8 | DY8: =EF7 | DZ8: 0 | EA8: =DY8+DZ8 | EB8: =K8 | EC8: 0.0002 | ED8: =EB8*EC8 | EE8: =EA8-ED8 | EF8: =EE8 | EG8: 4 | EH8: =DX8 | EI8: =EP7 | EJ8: 0 | EK8: =EI8+EJ8 | EL8: =L8 | EM8: 0.0006 | EN8: =EM8*EL8 | EO8: =EK8-EN8 | EP8: =EO8 | EQ8: =EF8+EP8 | ES8: 4 | ET8: =EH8 | EU8: =FB7 | EV8: 0 | EW8: =EU8+EV8 | EX8: =K8 | EY8: 0.002 | EZ8: =EX8*EY8 | FA8: =EW8-EZ8 | FB8: =FA8 | FC8: 4 | FD8: =ET8 | FE8: =FL7 | FF8: 0 | FG8: =FE8+FF8 | FH8: =L8 | FI8: 0.0025 | FJ8: =FI8*FH8 | FK8: =FG8-FJ8 | FL8: =FK8 | FM8: =FB8+FL8 | FO8: 4 | FP8: =FD8 | FQ8: =FX7 | FR8: 0 | FS8: =FQ8+FR8 | FT8: =K8 | FU8: 0.002 | FV8: =FT8*FU8 | FW8: =FS8-FV8 | FX8: =FW8 | FY8: 4 | FZ8: =FP8 | GA8: =GH7 | GB8: 0 | GC8: =GA8+GB8 | GD8: =L8 | GE8: 0.005 | GF8: =GE8*GD8 | GG8: =GC8-GF8 | GH8: =GG8 | GI8: =FX8+GH8 | GK8: 4 | GL8: =FZ8 | GM8: =GT7 | GN8: 0 | GO8: =GM8+GN8 | GP8: =K8 | GQ8: 0.005 | GR8: =GP8*GQ8 | GS8: =GO8-GR8 | GT8: =GS8 | GU8: 4 | GV8: =GL8 | GW8: =HD7 | GX8: 0 | GY8: =GW8+GX8 | GZ8: =L8 | HA8: 0.0075 | HB8: =HA8*GZ8 | HC8: =GY8-HB8 | HD8: =HC8 | HE8: =GT8+HD8 | HG8: 4 | HH8: =GV8 | HI8: =K8 | HJ8: 1 | HK8: =HI8*HJ8 | HL8: 0.89 | HM8: =HI8*HL8 | HN8: 0.7 | HO8: =HN8*HI8 | HP8: 2.59 | HQ8: =HI8*HP8 | HR8: 4 | HS8: 45023 | HT8: =L8 | HU8: 1.64 | HV8: =HT8*HU8 | HW8: 1.14 | HX8: =HT8*HW8 | HY8: 1.1 | HZ8: =HY8*HT8 | IA8: 3.11 | IB8: =HT8*IA8 | IC8: =HK8+HV8 | ID8: =HM8+HX8 | IE8: =HO8+HZ8 | IG8: =HH8 | IH8: jfookj | IJ8: =IJ7 | IK8: =IJ8 | IL8: =K8 | IM8: =IL8*100 | IN8: =IL8*20 | IQ8: =IL8*0.3 | IR8: =IL8*0.4 | IS8: =IL8*1.5 | IT8: =IL8*5 | IU8: =IL8*2 | IV8: =IL8*2.08 | IX8: =IL8*2.08 | IZ8: =IG8 | JA8: jfookj | JC8: =JC7 | JD8: =JC8 | JE8: =L8 | JF8: =JE8*150 | JG8: =JE8*30 | JJ8: =JE8*0.25 | JK8: =JE8*0.4 | JL8: =JE8*2.5 | JM8: =JE8*7.5 | JN8: =JE8*4 | JO8: =JE8*3.11 | JQ8: =JE8*3.11 | JT8: 3 | JU8: elqjnkG | JV8: =BR35 | JW8: =CB35 | JX8: =SUM(JV8:JW8) | KA8: 3 | KB8: elqjnkG | KC8: =JV8 | KD8: =BL36 | KE8: =BP36 | KG8: =JW8 | KH8: =BV36 | KI8: =BZ36
A9: jfookj | B9: 05/04/2026 | C9: 0 | D9: =C9 | E9: 0 | F9: 0 | G9: 0 | H9: =G9+F9+E9 | I9: jfookj | J9: 05/04/2026 | K9: =D9 | L9: =H9 | M9: =SUM(K9:L9) | Q9: 5 | R9: 05/04/2026 | S9: =Z8 | T9: 0 | U9: =S9+T9 | V9: =K9 | W9: 0.1 | X9: =V9*W9 | Y9: =U9-X9 | Z9: =Y9 | AA9: 5 | AB9: =R9 | AC9: =AJ8 | AD9: 0 | AE9: =AC9+AD9 | AF9: =L9 | AG9: 0.15 | AH9: =AG9*AF9 | AI9: =AE9-AH9 | AJ9: =AI9 | AK9: =Z9+AJ9 | AM9: 5 | AN9: =AB9 | AO9: =AV8 | AP9: 0 | AQ9: =AO9+AP9 | AR9: 0 | AS9: 0.02 | AT9: =AR9*AS9 | AU9: =AQ9-AT9 | AV9: =AU9 | AW9: 5 | AX9: =AN9 | AY9: =BF8 | AZ9: 0 | BA9: =AY9+AZ9 | BB9: 0 | BC9: 0.03 | BD9: =BC9*BB9 | BE9: =BA9-BD9 | BF9: =BE9 | BG9: =AV9+BF9 | BI9: 5 | BJ9: =AX9 | BK9: =BR8 | BL9: 0 | BM9: =BK9+BL9 | BN9: 0 | BO9: 0.02 | BP9: =BN9*BO9 | BQ9: =BM9-BP9 | BR9: =BQ9 | BS9: 5 | BT9: =BJ9 | BU9: =CB8 | BV9: 0 | BW9: =BU9+BV9 | BX9: 0 | BY9: 0.03 | BZ9: =BY9*BX9 | CA9: =BW9-BZ9 | CB9: =CA9 | CC9: =BR9+CB9 | CE9: 5 | CF9: =BT9 | CG9: =CN8 | CH9: 0 | CI9: =CG9+CH9 | CJ9: 0 | CK9: 0.02 | CL9: =CJ9*CK9 | CM9: =CI9-CL9 | CN9: =CM9 | CO9: 5 | CP9: =CF9 | CQ9: =CX8 | CR9: 0 | CS9: =CQ9+CR9 | CT9: 0 | CU9: 0.03 | CV9: =CU9*CT9 | CW9: =CS9-CV9 | CX9: =CW9 | CY9: =CN9+CX9 | DA9: 5 | DB9: =CP9 | DC9: =DJ8 | DD9: 0 | DE9: =DC9+DD9 | DF9: =K9 | DG9: 0.0001 | DH9: =DF9*DG9 | DI9: =DE9-DH9 | DJ9: =DI9 | DK9: 5 | DL9: =DB9 | DM9: =DT8 | DN9: 0 | DO9: =DM9+DN9 | DP9: =L9 | DQ9: 0.0003 | DR9: =DQ9*DP9 | DS9: =DO9-DR9 | DT9: =DS9 | DU9: =DJ9+DT9 | DW9: 5 | DX9: =DL9 | DY9: =EF8 | DZ9: 0 | EA9: =DY9+DZ9 | EB9: =K9 | EC9: 0.0002 | ED9: =EB9*EC9 | EE9: =EA9-ED9 | EF9: =EE9 | EG9: 5 | EH9: =DX9 | EI9: =EP8 | EJ9: 0 | EK9: =EI9+EJ9 | EL9: =L9 | EM9: 0.0006 | EN9: =EM9*EL9 | EO9: =EK9-EN9 | EP9: =EO9 | EQ9: =EF9+EP9 | ES9: 5 | ET9: =EH9 | EU9: =FB8 | EV9: 0 | EW9: =EU9+EV9 | EX9: =K9 | EY9: 0.002 | EZ9: =EX9*EY9 | FA9: =EW9-EZ9 | FB9: =FA9 | FC9: 5 | FD9: =ET9 | FE9: =FL8 | FF9: 0 | FG9: =FE9+FF9 | FH9: =L9 | FI9: 0.0025 | FJ9: =FI9*FH9 | FK9: =FG9-FJ9 | FL9: =FK9 | FM9: =FB9+FL9 | FO9: 5 | FP9: =FD9 | FQ9: =FX8 | FR9: 0 | FS9: =FQ9+FR9 | FT9: =K9 | FU9: 0.002 | FV9: =FT9*FU9 | FW9: =FS9-FV9 | FX9: =FW9 | FY9: 5 | FZ9: =FP9 | GA9: =GH8 | GB9: 0 | GC9: =GA9+GB9 | GD9: =L9 | GE9: 0.005 | GF9: =GE9*GD9 | GG9: =GC9-GF9 | GH9: =GG9 | GI9: =FX9+GH9 | GK9: 5 | GL9: =FZ9 | GM9: =GT8 | GN9: 0 | GO9: =GM9+GN9 | GP9: =K9 | GQ9: 0.005 | GR9: =GP9*GQ9 | GS9: =GO9-GR9 | GT9: =GS9 | GU9: 5 | GV9: =GL9 | GW9: =HD8 | GX9: 0 | GY9: =GW9+GX9 | GZ9: =L9 | HA9: 0.0075 | HB9: =HA9*GZ9 | HC9: =GY9-HB9 | HD9: =HC9 | HE9: =GT9+HD9 | HG9: 5 | HH9: =GV9 | HI9: =K9 | HJ9: 1 | HK9: =HI9*HJ9 | HL9: 0.89 | HM9: =HI9*HL9 | HN9: 0.7 | HO9: =HN9*HI9 | HP9: 2.59 | HQ9: =HI9*HP9 | HR9: 5 | HS9: 45053 | HT9: =L9 | HU9: 1.64 | HV9: =HT9*HU9 | HW9: 1.14 | HX9: =HT9*HW9 | HY9: 1.1 | HZ9: =HY9*HT9 | IA9: 3.11 | IB9: =HT9*IA9 | IC9: =HK9+HV9 | ID9: =HM9+HX9 | IE9: =HO9+HZ9 | IG9: =HH9 | IH9: lkseokj | II9: elqj nkG | IJ9: =IJ8 | IK9: =IJ9 | IL9: =K9 | IM9: =IL9*100 | IN9: =IL9*20 | IQ9: =IL9*0.3 | IR9: =IL9*0.4 | IS9: =IL9*1.5 | IT9: =IL9*5 | IU9: =IL9*2 | IV9: =IL9*2.08 | IX9: =IL9*2.08 | IZ9: =IG9 | JA9: lkseokj | JB9: elqj nkG | JC9: =JC8 | JD9: =JC9 | JE9: =L9 | JF9: =JE9*150 | JG9: =JE9*30 | JJ9: =JE9*0.25 | JK9: =JE9*0.4 | JL9: =JE9*2.5 | JM9: =JE9*7.5 | JN9: =JE9*4 | JO9: =JE9*3.11 | JQ9: =JE9*3.11 | JT9: 4 | JU9: eVdh@ poGh | JV9: =CN35 | JW9: =CX35 | JX9: =SUM(JV9:JW9) | KA9: 4 | KB9: gjHkjk | KC9: =JV9 | KD9: =CH36 | KE9: =CL36 | KG9: =JW9 | KH9: =CR36 | KI9: =CV36
A10: lkseokj | B10: 06/04/2026 | C10: 0 | D10: =C10 | E10: 0 | F10: 0 | G10: 0 | H10: =G10+F10+E10 | I10: lkseokj | J10: 06/04/2026 | K10: =D10 | L10: =H10 | M10: =SUM(K10:L10) | N10: elqj nkG | Q10: 6 | R10: 06/04/2026 | S10: =Z9 | T10: 0 | U10: =S10+T10 | V10: =K10 | W10: 0.1 | X10: =V10*W10 | Y10: =U10-X10 | Z10: =Y10 | AA10: 6 | AB10: =R10 | AC10: =AJ9 | AD10: 0 | AE10: =AC10+AD10 | AF10: =L10 | AG10: 0.15 | AH10: =AG10*AF10 | AI10: =AE10-AH10 | AJ10: =AI10 | AK10: =Z10+AJ10 | AM10: 6 | AN10: =AB10 | AO10: =AV9 | AP10: 0 | AQ10: =AO10+AP10 | AR10: 0 | AS10: 0.02 | AT10: =AR10*AS10 | AU10: =AQ10-AT10 | AV10: =AU10 | AW10: 6 | AX10: =AN10 | AY10: =BF9 | AZ10: 0 | BA10: =AY10+AZ10 | BB10: 0 | BC10: 0.03 | BD10: =BC10*BB10 | BE10: =BA10-BD10 | BF10: =BE10 | BG10: =AV10+BF10 | BI10: 6 | BJ10: =AX10 | BK10: =BR9 | BL10: 0 | BM10: =BK10+BL10 | BN10: =K10 | BO10: 0.02 | BP10: =BN10*BO10 | BQ10: =BM10-BP10 | BR10: =BQ10 | BS10: 6 | BT10: =BJ10 | BU10: =CB9 | BV10: 0 | BW10: =BU10+BV10 | BX10: =L10 | BY10: 0.03 | BZ10: =BY10*BX10 | CA10: =BW10-BZ10 | CB10: =CA10 | CC10: =BR10+CB10 | CE10: 6 | CF10: =BT10 | CG10: =CN9 | CH10: 0 | CI10: =CG10+CH10 | CJ10: 0 | CK10: 0.02 | CL10: =CJ10*CK10 | CM10: =CI10-CL10 | CN10: =CM10 | CO10: 6 | CP10: =CF10 | CQ10: =CX9 | CR10: 0 | CS10: =CQ10+CR10 | CT10: 0 | CU10: 0.03 | CV10: =CU10*CT10 | CW10: =CS10-CV10 | CX10: =CW10 | CY10: =CN10+CX10 | DA10: 6 | DB10: =CP10 | DC10: =DJ9 | DD10: 0 | DE10: =DC10+DD10 | DF10: =K10 | DG10: 0.0001 | DH10: =DF10*DG10 | DI10: =DE10-DH10 | DJ10: =DI10 | DK10: 6 | DL10: =DB10 | DM10: =DT9 | DN10: 0 | DO10: =DM10+DN10 | DP10: =L10 | DQ10: 0.0003 | DR10: =DQ10*DP10 | DS10: =DO10-DR10 | DT10: =DS10 | DU10: =DJ10+DT10 | DW10: 6 | DX10: =DL10 | DY10: =EF9 | DZ10: 0 | EA10: =DY10+DZ10 | EB10: =K10 | EC10: 0.0002 | ED10: =EB10*EC10 | EE10: =EA10-ED10 | EF10: =EE10 | EG10: 6 | EH10: =DX10 | EI10: =EP9 | EJ10: 0 | EK10: =EI10+EJ10 | EL10: =L10 | EM10: 0.0006 | EN10: =EM10*EL10 | EO10: =EK10-EN10 | EP10: =EO10 | EQ10: =EF10+EP10 | ES10: 6 | ET10: =EH10 | EU10: =FB9 | EV10: 0 | EW10: =EU10+EV10 | EX10: =K10 | EY10: 0.002 | EZ10: =EX10*EY10 | FA10: =EW10-EZ10 | FB10: =FA10 | FC10: 6 | FD10: =ET10 | FE10: =FL9 | FF10: 0 | FG10: =FE10+FF10 | FH10: =L10 | FI10: 0.0025 | FJ10: =FI10*FH10 | FK10: =FG10-FJ10 | FL10: =FK10 | FM10: =FB10+FL10 | FO10: 6 | FP10: =FD10 | FQ10: =FX9 | FR10: 0 | FS10: =FQ10+FR10 | FT10: =K10 | FU10: 0.002 | FV10: =FT10*FU10 | FW10: =FS10-FV10 | FX10: =FW10 | FY10: 6 | FZ10: =FP10 | GA10: =GH9 | GB10: 0 | GC10: =GA10+GB10 | GD10: =L10 | GE10: 0.005 | GF10: =GE10*GD10 | GG10: =GC10-GF10 | GH10: =GG10 | GI10: =FX10+GH10 | GK10: 6 | GL10: =FZ10 | GM10: =GT9 | GN10: 0 | GO10: =GM10+GN10 | GP10: =K10 | GQ10: 0.005 | GR10: =GP10*GQ10 | GS10: =GO10-GR10 | GT10: =GS10 | GU10: 6 | GV10: =GL10 | GW10: =HD9 | GX10: 0 | GY10: =GW10+GX10 | GZ10: =L10 | HA10: 0.0075 | HB10: =HA10*GZ10 | HC10: =GY10-HB10 | HD10: =HC10 | HE10: =GT10+HD10 | HG10: 6 | HH10: =GV10 | HI10: =K10 | HJ10: 1 | HK10: =HI10*HJ10 | HL10: 0.89 | HM10: =HI10*HL10 | HN10: 0.7 | HO10: =HN10*HI10 | HP10: 2.59 | HQ10: =HI10*HP10 | HR10: 6 | HS10: 45084 | HT10: =L10 | HU10: 1.64 | HV10: =HT10*HU10 | HW10: 1.14 | HX10: =HT10*HW10 | HY10: 1.1 | HZ10: =HY10*HT10 | IA10: 3.11 | IB10: =HT10*IA10 | IC10: =HK10+HV10 | ID10: =HM10+HX10 | IE10: =HO10+HZ10 | IG10: =HH10 | IH10: eaxGokj | II10: okVk.kk | IJ10: =IJ9 | IK10: =IJ10 | IL10: =K10 | IM10: =IL10*100 | IO10: =IL10*20 | IQ10: =IL10*0.3 | IR10: =IL10*0.4 | IS10: =IL10*1.5 | IT10: =IL10*5 | IU10: =IL10*2 | IV10: =IL10*2.08 | IX10: =IL10*2.08 | IZ10: =IG10 | JA10: eaxGokj | JB10: okVk.kk | JC10: =JC9 | JD10: =JC10 | JE10: =L10 | JF10: =JE10*150 | JH10: =JE10*30 | JJ10: =JE10*0.25 | JK10: =JE10*0.4 | JL10: =JE10*2.5 | JM10: =JE10*7.5 | JN10: =JE10*4 | JO10: =JE10*3.11 | JQ10: =JE10*3.11 | JT10: 5 | JU10: gjcjk | JV10: =AV35 | JW10: =BF35 | JX10: =SUM(JV10:JW10) | KA10: 5 | KB10: okVk.kk | KC10: =JV10 | KD10: =AP36 | KE10: =AT36 | KG10: =JW10 | KH10: =AZ36 | KI10: =BD36
A11: eaxGokj | B11: 07/04/2026 | C11: 0 | D11: =C11 | E11: 0 | F11: 0 | G11: 0 | H11: =G11+F11+E11 | I11: eaxGokj | J11: 07/04/2026 | K11: =D11 | L11: =H11 | M11: =SUM(K11:L11) | N11: gjcjk | Q11: 7 | R11: 07/04/2026 | S11: =Z10 | T11: 0 | U11: =S11+T11 | V11: =K11 | W11: 0.1 | X11: =V11*W11 | Y11: =U11-X11 | Z11: =Y11 | AA11: 7 | AB11: =R11 | AC11: =AJ10 | AD11: 0 | AE11: =AC11+AD11 | AF11: =L11 | AG11: 0.15 | AH11: =AG11*AF11 | AI11: =AE11-AH11 | AJ11: =AI11 | AK11: =Z11+AJ11 | AM11: 7 | AN11: =AB11 | AO11: =AV10 | AP11: 0 | AQ11: =AO11+AP11 | AR11: =K11 | AS11: 0.02 | AT11: =AR11*AS11 | AU11: =AQ11-AT11 | AV11: =AU11 | AW11: 7 | AX11: =AN11 | AY11: =BF10 | AZ11: 0 | BA11: =AY11+AZ11 | BB11: =L11 | BC11: 0.03 | BD11: =BC11*BB11 | BE11: =BA11-BD11 | BF11: =BE11 | BG11: =AV11+BF11 | BI11: 7 | BJ11: =AX11 | BK11: =BR10 | BL11: 0 | BM11: =BK11+BL11 | BN11: 0 | BO11: 0.02 | BP11: =BN11*BO11 | BQ11: =BM11-BP11 | BR11: =BQ11 | BS11: 7 | BT11: =BJ11 | BU11: =CB10 | BV11: 0 | BW11: =BU11+BV11 | BX11: 0 | BY11: 0.03 | BZ11: =BY11*BX11 | CA11: =BW11-BZ11 | CB11: =CA11 | CC11: =BR11+CB11 | CE11: 7 | CF11: =BT11 | CG11: =CN10 | CH11: 0 | CI11: =CG11+CH11 | CJ11: 0 | CK11: 0.02 | CL11: =CJ11*CK11 | CM11: =CI11-CL11 | CN11: =CM11 | CO11: 7 | CP11: =CF11 | CQ11: =CX10 | CR11: 0 | CS11: =CQ11+CR11 | CT11: 0 | CU11: 0.03 | CV11: =CU11*CT11 | CW11: =CS11-CV11 | CX11: =CW11 | CY11: =CN11+CX11 | DA11: 7 | DB11: =CP11 | DC11: =DJ10 | DD11: 0 | DE11: =DC11+DD11 | DF11: =K11 | DG11: 0.0001 | DH11: =DF11*DG11 | DI11: =DE11-DH11 | DJ11: =DI11 | DK11: 7 | DL11: =DB11 | DM11: =DT10 | DN11: 0 | DO11: =DM11+DN11 | DP11: =L11 | DQ11: 0.0003 | DR11: =DQ11*DP11 | DS11: =DO11-DR11 | DT11: =DS11 | DU11: =DJ11+DT11 | DW11: 7 | DX11: =DL11 | DY11: =EF10 | DZ11: 0 | EA11: =DY11+DZ11 | EB11: =K11 | EC11: 0.0002 | ED11: =EB11*EC11 | EE11: =EA11-ED11 | EF11: =EE11 | EG11: 7 | EH11: =DX11 | EI11: =EP10 | EJ11: 0 | EK11: =EI11+EJ11 | EL11: =L11 | EM11: 0.0006 | EN11: =EM11*EL11 | EO11: =EK11-EN11 | EP11: =EO11 | EQ11: =EF11+EP11 | ES11: 7 | ET11: =EH11 | EU11: =FB10 | EV11: 0 | EW11: =EU11+EV11 | EX11: =K11 | EY11: 0.002 | EZ11: =EX11*EY11 | FA11: =EW11-EZ11 | FB11: =FA11 | FC11: 7 | FD11: =ET11 | FE11: =FL10 | FF11: 0 | FG11: =FE11+FF11 | FH11: =L11 | FI11: 0.0025 | FJ11: =FI11*FH11 | FK11: =FG11-FJ11 | FL11: =FK11 | FM11: =FB11+FL11 | FO11: 7 | FP11: =FD11 | FQ11: =FX10 | FR11: 0 | FS11: =FQ11+FR11 | FT11: =K11 | FU11: 0.002 | FV11: =FT11*FU11 | FW11: =FS11-FV11 | FX11: =FW11 | FY11: 7 | FZ11: =FP11 | GA11: =GH10 | GB11: 0 | GC11: =GA11+GB11 | GD11: =L11 | GE11: 0.005 | GF11: =GE11*GD11 | GG11: =GC11-GF11 | GH11: =GG11 | GI11: =FX11+GH11 | GK11: 7 | GL11: =FZ11 | GM11: =GT10 | GN11: 0 | GO11: =GM11+GN11 | GP11: =K11 | GQ11: 0.005 | GR11: =GP11*GQ11 | GS11: =GO11-GR11 | GT11: =GS11 | GU11: 7 | GV11: =GL11 | GW11: =HD10 | GX11: 0 | GY11: =GW11+GX11 | GZ11: =L11 | HA11: 0.0075 | HB11: =HA11*GZ11 | HC11: =GY11-HB11 | HD11: =HC11 | HE11: =GT11+HD11 | HG11: 7 | HH11: =GV11 | HI11: =K11 | HJ11: 1 | HK11: =HI11*HJ11 | HL11: 0.89 | HM11: =HI11*HL11 | HN11: 0.7 | HO11: =HN11*HI11 | HP11: 2.59 | HQ11: =HI11*HP11 | HR11: 7 | HS11: 45114 | HT11: =L11 | HU11: 1.64 | HV11: =HT11*HU11 | HW11: 1.14 | HX11: =HT11*HW11 | HY11: 1.1 | HZ11: =HY11*HT11 | IA11: 3.11 | IB11: =HT11*IA11 | IC11: =HK11+HV11 | ID11: =HM11+HX11 | IE11: =HO11+HZ11 | IG11: =HH11 | IH11: cq/kokj | II11: gjcjk | IJ11: =IJ10 | IK11: =IJ11 | IL11: =K11 | IM11: =IL11*100 | IP11: =IL11*20 | IQ11: =IL11*0.3 | IR11: =IL11*0.4 | IS11: =IL11*1.5 | IT11: =IL11*5 | IU11: =IL11*2 | IV11: =IL11*2.08 | IX11: =IL11*2.08 | IZ11: =IG11 | JA11: cq/kokj | JB11: gjcjk | JC11: =JC10 | JD11: =JC11 | JE11: =L11 | JF11: =JE11*150 | JI11: =JE11*30 | JJ11: =JE11*0.25 | JK11: =JE11*0.4 | JL11: =JE11*2.5 | JM11: =JE11*7.5 | JN11: =JE11*4 | JO11: =JE11*3.11 | JQ11: =JE11*3.11 | JT11: 6 | JU11: eksgjh | JV11: =DJ35 | JW11: =DT35 | JX11: =SUM(JV11:JW11) | KA11: 6 | KB11: eksgjh | KC11: =JV11 | KD11: =DD36 | KE11: =DH36 | KG11: =JW11 | KH11: =DN36 | KI11: =DR36
A12: cq/kokj | B12: 08/04/2026 | C12: 0 | D12: =C12 | E12: 0 | F12: 0 | G12: 0 | H12: =G12+F12+E12 | I12: cq/kokj | J12: 08/04/2026 | K12: =D12 | L12: =H12 | M12: =SUM(K12:L12) | N12: eVdh | Q12: 8 | R12: 08/04/2026 | S12: =Z11 | T12: 0 | U12: =S12+T12 | V12: =K12 | W12: 0.1 | X12: =V12*W12 | Y12: =U12-X12 | Z12: =Y12 | AA12: 8 | AB12: =R12 | AC12: =AJ11 | AD12: 0 | AE12: =AC12+AD12 | AF12: =L12 | AG12: 0.15 | AH12: =AG12*AF12 | AI12: =AE12-AH12 | AJ12: =AI12 | AK12: =Z12+AJ12 | AM12: 8 | AN12: =AB12 | AO12: =AV11 | AP12: 0 | AQ12: =AO12+AP12 | AR12: 0 | AS12: 0.02 | AT12: =AR12*AS12 | AU12: =AQ12-AT12 | AV12: =AU12 | AW12: 8 | AX12: =AN12 | AY12: =BF11 | AZ12: 0 | BA12: =AY12+AZ12 | BB12: 0 | BC12: 0.03 | BD12: =BC12*BB12 | BE12: =BA12-BD12 | BF12: =BE12 | BG12: =AV12+BF12 | BI12: 8 | BJ12: =AX12 | BK12: =BR11 | BL12: 0 | BM12: =BK12+BL12 | BN12: 0 | BO12: 0.02 | BP12: =BN12*BO12 | BQ12: =BM12-BP12 | BR12: =BQ12 | BS12: 8 | BT12: =BJ12 | BU12: =CB11 | BV12: 0 | BW12: =BU12+BV12 | BX12: 0 | BY12: 0.03 | BZ12: =BY12*BX12 | CA12: =BW12-BZ12 | CB12: =CA12 | CC12: =BR12+CB12 | CE12: 8 | CF12: =BT12 | CG12: =CN11 | CH12: 0 | CI12: =CG12+CH12 | CJ12: =K12 | CK12: 0.02 | CL12: =CJ12*CK12 | CM12: =CI12-CL12 | CN12: =CM12 | CO12: 8 | CP12: =CF12 | CQ12: =CX11 | CR12: 0 | CS12: =CQ12+CR12 | CT12: =L12 | CU12: 0.03 | CV12: =CU12*CT12 | CW12: =CS12-CV12 | CX12: =CW12 | CY12: =CN12+CX12 | DA12: 8 | DB12: =CP12 | DC12: =DJ11 | DD12: 0 | DE12: =DC12+DD12 | DF12: =K12 | DG12: 0.0001 | DH12: =DF12*DG12 | DI12: =DE12-DH12 | DJ12: =DI12 | DK12: 8 | DL12: =DB12 | DM12: =DT11 | DN12: 0 | DO12: =DM12+DN12 | DP12: =L12 | DQ12: 0.0003 | DR12: =DQ12*DP12 | DS12: =DO12-DR12 | DT12: =DS12 | DU12: =DJ12+DT12 | DW12: 8 | DX12: =DL12 | DY12: =EF11 | DZ12: 0 | EA12: =DY12+DZ12 | EB12: =K12 | EC12: 0.0002 | ED12: =EB12*EC12 | EE12: =EA12-ED12 | EF12: =EE12 | EG12: 8 | EH12: =DX12 | EI12: =EP11 | EJ12: 0 | EK12: =EI12+EJ12 | EL12: =L12 | EM12: 0.0006 | EN12: =EM12*EL12 | EO12: =EK12-EN12 | EP12: =EO12 | EQ12: =EF12+EP12 | ES12: 8 | ET12: =EH12 | EU12: =FB11 | EV12: 0 | EW12: =EU12+EV12 | EX12: =K12 | EY12: 0.002 | EZ12: =EX12*EY12 | FA12: =EW12-EZ12 | FB12: =FA12 | FC12: 8 | FD12: =ET12 | FE12: =FL11 | FF12: 0 | FG12: =FE12+FF12 | FH12: =L12 | FI12: 0.0025 | FJ12: =FI12*FH12 | FK12: =FG12-FJ12 | FL12: =FK12 | FM12: =FB12+FL12 | FO12: 8 | FP12: =FD12 | FQ12: =FX11 | FR12: 0 | FS12: =FQ12+FR12 | FT12: =K12 | FU12: 0.002 | FV12: =FT12*FU12 | FW12: =FS12-FV12 | FX12: =FW12 | FY12: 8 | FZ12: =FP12 | GA12: =GH11 | GB12: 0 | GC12: =GA12+GB12 | GD12: =L12 | GE12: 0.005 | GF12: =GE12*GD12 | GG12: =GC12-GF12 | GH12: =GG12 | GI12: =FX12+GH12 | GK12: 8 | GL12: =FZ12 | GM12: =GT11 | GN12: 0 | GO12: =GM12+GN12 | GP12: =K12 | GQ12: 0.005 | GR12: =GP12*GQ12 | GS12: =GO12-GR12 | GT12: =GS12 | GU12: 8 | GV12: =GL12 | GW12: =HD11 | GX12: 0 | GY12: =GW12+GX12 | GZ12: =L12 | HA12: 0.0075 | HB12: =HA12*GZ12 | HC12: =GY12-HB12 | HD12: =HC12 | HE12: =GT12+HD12 | HG12: 8 | HH12: =GV12 | HI12: =K12 | HJ12: 1 | HK12: =HI12*HJ12 | HL12: 0.89 | HM12: =HI12*HL12 | HN12: 0.7 | HO12: =HN12*HI12 | HP12: 2.59 | HQ12: =HI12*HP12 | HR12: 8 | HS12: 45145 | HT12: =L12 | HU12: 1.64 | HV12: =HT12*HU12 | HW12: 1.14 | HX12: =HT12*HW12 | HY12: 1.1 | HZ12: =HY12*HT12 | IA12: 3.11 | IB12: =HT12*IA12 | IC12: =HK12+HV12 | ID12: =HM12+HX12 | IE12: =HO12+HZ12 | IG12: =HH12 | IH12: xq:okj | II12: elqj nkG | IJ12: =IJ11 | IK12: =IJ12 | IL12: =K12 | IM12: =IL12*100 | IN12: =IL12*20 | IQ12: =IL12*0.3 | IR12: =IL12*0.4 | IS12: =IL12*1.5 | IT12: =IL12*5 | IU12: =IL12*2 | IV12: =IL12*2.08 | IX12: =IL12*2.08 | IZ12: =IG12 | JA12: xq:okj | JB12: elqj nkG | JC12: =JC11 | JD12: =JC12 | JE12: =L12 | JF12: =JE12*150 | JG12: =JE12*30 | JJ12: =JE12*0.25 | JK12: =JE12*0.4 | JL12: =JE12*2.5 | JM12: =JE12*7.5 | JN12: =JE12*4 | JO12: =JE12*3.11 | JQ12: =JE12*3.11 | JT12: 6 | JV12: =DJ36 | JW12: =DT36 | JX12: =SUM(JV12:JW12) | KA12: 6 | KC12: =JV12 | KG12: =JW12
A13: xq:okj | B13: 09/04/2026 | C13: 0 | D13: =C13 | E13: 0 | F13: 0 | G13: 0 | H13: =G13+F13+E13 | I13: xq:okj | J13: 09/04/2026 | K13: =D13 | L13: =H13 | M13: =SUM(K13:L13) | N13: elqj nkG | Q13: 9 | R13: 09/04/2026 | S13: =Z12 | T13: 0 | U13: =S13+T13 | V13: =K13 | W13: 0.1 | X13: =V13*W13 | Y13: =U13-X13 | Z13: =Y13 | AA13: 9 | AB13: =R13 | AC13: =AJ12 | AD13: 0 | AE13: =AC13+AD13 | AF13: =L13 | AG13: 0.15 | AH13: =AG13*AF13 | AI13: =AE13-AH13 | AJ13: =AI13 | AK13: =Z13+AJ13 | AM13: 9 | AN13: =AB13 | AO13: =AV12 | AP13: 0 | AQ13: =AO13+AP13 | AR13: 0 | AS13: 0.02 | AT13: =AR13*AS13 | AU13: =AQ13-AT13 | AV13: =AU13 | AW13: 9 | AX13: =AN13 | AY13: =BF12 | AZ13: 0 | BA13: =AY13+AZ13 | BB13: 0 | BC13: 0.03 | BD13: =BC13*BB13 | BE13: =BA13-BD13 | BF13: =BE13 | BG13: =AV13+BF13 | BI13: 9 | BJ13: =AX13 | BK13: =BR12 | BL13: 0 | BM13: =BK13+BL13 | BN13: =K13 | BO13: 0.02 | BP13: =BN13*BO13 | BQ13: =BM13-BP13 | BR13: =BQ13 | BS13: 9 | BT13: =BJ13 | BU13: =CB12 | BV13: 0 | BW13: =BU13+BV13 | BX13: =L13 | BY13: 0.03 | BZ13: =BY13*BX13 | CA13: =BW13-BZ13 | CB13: =CA13 | CC13: =BR13+CB13 | CE13: 9 | CF13: =BT13 | CG13: =CN12 | CH13: 0 | CI13: =CG13+CH13 | CJ13: 0 | CK13: 0.02 | CL13: =CJ13*CK13 | CM13: =CI13-CL13 | CN13: =CM13 | CO13: 9 | CP13: =CF13 | CQ13: =CX12 | CR13: 0 | CS13: =CQ13+CR13 | CT13: 0 | CU13: 0.03 | CV13: =CU13*CT13 | CW13: =CS13-CV13 | CX13: =CW13 | CY13: =CN13+CX13 | DA13: 9 | DB13: =CP13 | DC13: =DJ12 | DD13: 0 | DE13: =DC13+DD13 | DF13: =K13 | DG13: 0.0001 | DH13: =DF13*DG13 | DI13: =DE13-DH13 | DJ13: =DI13 | DK13: 9 | DL13: =DB13 | DM13: =DT12 | DN13: 0 | DO13: =DM13+DN13 | DP13: =L13 | DQ13: 0.0003 | DR13: =DQ13*DP13 | DS13: =DO13-DR13 | DT13: =DS13 | DU13: =DJ13+DT13 | DW13: 9 | DX13: =DL13 | DY13: =EF12 | DZ13: 0 | EA13: =DY13+DZ13 | EB13: =K13 | EC13: 0.0002 | ED13: =EB13*EC13 | EE13: =EA13-ED13 | EF13: =EE13 | EG13: 9 | EH13: =DX13 | EI13: =EP12 | EJ13: 0 | EK13: =EI13+EJ13 | EL13: =L13 | EM13: 0.0006 | EN13: =EM13*EL13 | EO13: =EK13-EN13 | EP13: =EO13 | EQ13: =EF13+EP13 | ES13: 9 | ET13: =EH13 | EU13: =FB12 | EV13: 0 | EW13: =EU13+EV13 | EX13: =K13 | EY13: 0.002 | EZ13: =EX13*EY13 | FA13: =EW13-EZ13 | FB13: =FA13 | FC13: 9 | FD13: =ET13 | FE13: =FL12 | FF13: 0 | FG13: =FE13+FF13 | FH13: =L13 | FI13: 0.0025 | FJ13: =FI13*FH13 | FK13: =FG13-FJ13 | FL13: =FK13 | FM13: =FB13+FL13 | FO13: 9 | FP13: =FD13 | FQ13: =FX12 | FR13: 0 | FS13: =FQ13+FR13 | FT13: =K13 | FU13: 0.002 | FV13: =FT13*FU13 | FW13: =FS13-FV13 | FX13: =FW13 | FY13: 9 | FZ13: =FP13 | GA13: =GH12 | GB13: 0 | GC13: =GA13+GB13 | GD13: =L13 | GE13: 0.005 | GF13: =GE13*GD13 | GG13: =GC13-GF13 | GH13: =GG13 | GI13: =FX13+GH13 | GK13: 9 | GL13: =FZ13 | GM13: =GT12 | GN13: 0 | GO13: =GM13+GN13 | GP13: =K13 | GQ13: 0.005 | GR13: =GP13*GQ13 | GS13: =GO13-GR13 | GT13: =GS13 | GU13: 9 | GV13: =GL13 | GW13: =HD12 | GX13: 0 | GY13: =GW13+GX13 | GZ13: =L13 | HA13: 0.0075 | HB13: =HA13*GZ13 | HC13: =GY13-HB13 | HD13: =HC13 | HE13: =GT13+HD13 | HG13: 9 | HH13: =GV13 | HI13: =K13 | HJ13: 1 | HK13: =HI13*HJ13 | HL13: 0.89 | HM13: =HI13*HL13 | HN13: 0.7 | HO13: =HN13*HI13 | HP13: 2.59 | HQ13: =HI13*HP13 | HR13: 9 | HS13: 45176 | HT13: =L13 | HU13: 1.64 | HV13: =HT13*HU13 | HW13: 1.14 | HX13: =HT13*HW13 | HY13: 1.1 | HZ13: =HY13*HT13 | IA13: 3.11 | IB13: =HT13*IA13 | IC13: =HK13+HV13 | ID13: =HM13+HX13 | IE13: =HO13+HZ13 | IG13: =HH13 | IH13: 'kqdzokj | II13: okVk.kk | IJ13: =IJ12 | IK13: =IJ13 | IL13: =K13 | IM13: =IL13*100 | IO13: =IL13*20 | IQ13: =IL13*0.3 | IR13: =IL13*0.4 | IS13: =IL13*1.5 | IT13: =IL13*5 | IU13: =IL13*2 | IV13: =IL13*2.08 | IX13: =IL13*2.08 | IZ13: =IG13 | JA13: 'kqdzokj | JB13: okVk.kk | JC13: =JC12 | JD13: =JC13 | JE13: =L13 | JF13: =JE13*150 | JH13: =JE13*30 | JJ13: =JE13*0.25 | JK13: =JE13*0.4 | JL13: =JE13*2.5 | JM13: =JE13*7.5 | JN13: =JE13*4 | JO13: =JE13*3.11 | JQ13: =JE13*3.11 | JT13: 7 | JU13: gGn | JV13: =EF35 | JW13: =EP35 | JX13: =SUM(JV13:JW13) | KA13: 7 | KB13: gGn | KC13: =JV13 | KD13: =DZ36 | KE13: =ED36 | KG13: =JW13 | KH13: =EJ36 | KI13: =EN36
A14: 'kqdzokj | B14: 10/04/2026 | C14: 0 | D14: =C14 | E14: 0 | F14: 0 | G14: 0 | H14: =G14+F14+E14 | I14: 'kqdzokj | J14: 10/04/2026 | K14: =D14 | L14: =H14 | M14: =SUM(K14:L14) | N14: poGh | Q14: 10 | R14: 10/04/2026 | S14: =Z13 | T14: 0 | U14: =S14+T14 | V14: =K14 | W14: 0.1 | X14: =V14*W14 | Y14: =U14-X14 | Z14: =Y14 | AA14: 10 | AB14: =R14 | AC14: =AJ13 | AD14: 0 | AE14: =AC14+AD14 | AF14: =L14 | AG14: 0.15 | AH14: =AG14*AF14 | AI14: =AE14-AH14 | AJ14: =AI14 | AK14: =Z14+AJ14 | AM14: 10 | AN14: =AB14 | AO14: =AV13 | AP14: 0 | AQ14: =AO14+AP14 | AR14: 0 | AS14: 0.02 | AT14: =AR14*AS14 | AU14: =AQ14-AT14 | AV14: =AU14 | AW14: 10 | AX14: =AN14 | AY14: =BF13 | AZ14: 0 | BA14: =AY14+AZ14 | BB14: 0 | BC14: 0.03 | BD14: =BC14*BB14 | BE14: =BA14-BD14 | BF14: =BE14 | BG14: =AV14+BF14 | BI14: 10 | BJ14: =AX14 | BK14: =BR13 | BL14: 0 | BM14: =BK14+BL14 | BN14: 0 | BO14: 0.02 | BP14: =BN14*BO14 | BQ14: =BM14-BP14 | BR14: =BQ14 | BS14: 10 | BT14: =BJ14 | BU14: =CB13 | BV14: 0 | BW14: =BU14+BV14 | BX14: 0 | BY14: 0.03 | BZ14: =BY14*BX14 | CA14: =BW14-BZ14 | CB14: =CA14 | CC14: =BR14+CB14 | CE14: 10 | CF14: =BT14 | CG14: =CN13 | CH14: 0 | CI14: =CG14+CH14 | CJ14: =K14 | CK14: 0.02 | CL14: =CJ14*CK14 | CM14: =CI14-CL14 | CN14: =CM14 | CO14: 10 | CP14: =CF14 | CQ14: =CX13 | CR14: 0 | CS14: =CQ14+CR14 | CT14: =L14 | CU14: 0.03 | CV14: =CU14*CT14 | CW14: =CS14-CV14 | CX14: =CW14 | CY14: =CN14+CX14 | DA14: 10 | DB14: =CP14 | DC14: =DJ13 | DD14: 0 | DE14: =DC14+DD14 | DF14: =K14 | DG14: 0.0001 | DH14: =DF14*DG14 | DI14: =DE14-DH14 | DJ14: =DI14 | DK14: 10 | DL14: =DB14 | DM14: =DT13 | DN14: 0 | DO14: =DM14+DN14 | DP14: =L14 | DQ14: 0.0003 | DR14: =DQ14*DP14 | DS14: =DO14-DR14 | DT14: =DS14 | DU14: =DJ14+DT14 | DW14: 10 | DX14: =DL14 | DY14: =EF13 | DZ14: 0 | EA14: =DY14+DZ14 | EB14: =K14 | EC14: 0.0002 | ED14: =EB14*EC14 | EE14: =EA14-ED14 | EF14: =EE14 | EG14: 10 | EH14: =DX14 | EI14: =EP13 | EJ14: 0 | EK14: =EI14+EJ14 | EL14: =L14 | EM14: 0.0006 | EN14: =EM14*EL14 | EO14: =EK14-EN14 | EP14: =EO14 | EQ14: =EF14+EP14 | ES14: 10 | ET14: =EH14 | EU14: =FB13 | EV14: 0 | EW14: =EU14+EV14 | EX14: =K14 | EY14: 0.002 | EZ14: =EX14*EY14 | FA14: =EW14-EZ14 | FB14: =FA14 | FC14: 10 | FD14: =ET14 | FE14: =FL13 | FF14: 0 | FG14: =FE14+FF14 | FH14: =L14 | FI14: 0.0025 | FJ14: =FI14*FH14 | FK14: =FG14-FJ14 | FL14: =FK14 | FM14: =FB14+FL14 | FO14: 10 | FP14: =FD14 | FQ14: =FX13 | FR14: 0 | FS14: =FQ14+FR14 | FT14: =K14 | FU14: 0.002 | FV14: =FT14*FU14 | FW14: =FS14-FV14 | FX14: =FW14 | FY14: 10 | FZ14: =FP14 | GA14: =GH13 | GB14: 0 | GC14: =GA14+GB14 | GD14: =L14 | GE14: 0.005 | GF14: =GE14*GD14 | GG14: =GC14-GF14 | GH14: =GG14 | GI14: =FX14+GH14 | GK14: 10 | GL14: =FZ14 | GM14: =GT13 | GN14: 0 | GO14: =GM14+GN14 | GP14: =K14 | GQ14: 0.005 | GR14: =GP14*GQ14 | GS14: =GO14-GR14 | GT14: =GS14 | GU14: 10 | GV14: =GL14 | GW14: =HD13 | GX14: 0 | GY14: =GW14+GX14 | GZ14: =L14 | HA14: 0.0075 | HB14: =HA14*GZ14 | HC14: =GY14-HB14 | HD14: =HC14 | HE14: =GT14+HD14 | HG14: 10 | HH14: =GV14 | HI14: =K14 | HJ14: 1 | HK14: =HI14*HJ14 | HL14: 0.89 | HM14: =HI14*HL14 | HN14: 0.7 | HO14: =HN14*HI14 | HP14: 2.59 | HQ14: =HI14*HP14 | HR14: 10 | HS14: 45206 | HT14: =L14 | HU14: 1.64 | HV14: =HT14*HU14 | HW14: 1.14 | HX14: =HT14*HW14 | HY14: 1.1 | HZ14: =HY14*HT14 | IA14: 3.11 | IB14: =HT14*IA14 | IC14: =HK14+HV14 | ID14: =HM14+HX14 | IE14: =HO14+HZ14 | IG14: =HH14 | IH14: 'kfuokj | II14: gjcjk | IJ14: =IJ13 | IK14: =IJ14 | IL14: =K14 | IM14: =IL14*100 | IP14: =IL14*20 | IQ14: =IL14*0.3 | IR14: =IL14*0.4 | IS14: =IL14*1.5 | IT14: =IL14*5 | IU14: =IL14*2 | IV14: =IL14*2.08 | IX14: =IL14*2.08 | IZ14: =IG14 | JA14: 'kfuokj | JB14: gjcjk | JC14: =JC13 | JD14: =JC14 | JE14: =L14 | JF14: =JE14*150 | JI14: =JE14*30 | JJ14: =JE14*0.25 | JK14: =JE14*0.4 | JL14: =JE14*2.5 | JM14: =JE14*7.5 | JN14: =JE14*4 | JO14: =JE14*3.11 | JQ14: =JE14*3.11 | JT14: 8 | JU14: dkank ylw.k elkyk | JV14: =FB35 | JW14: =FL35 | JX14: =SUM(JV14:JW14) | KA14: 8 | KB14: dkank ylw.k elkyk | KC14: =JV14 | KD14: =EV36 | KE14: =EZ36 | KG14: =JW14 | KH14: =FF36 | KI14: =FJ36
A15: 'kfuokj | B15: 11/04/2026 | C15: 0 | D15: =C15 | E15: 0 | F15: 0 | G15: 0 | H15: =G15+F15+E15 | I15: 'kfuokj | J15: 11/04/2026 | K15: =D15 | L15: =H15 | M15: =SUM(K15:L15) | N15: gjcjk | Q15: 11 | R15: 11/04/2026 | S15: =Z14 | T15: 0 | U15: =S15+T15 | V15: =K15 | W15: 0.1 | X15: =V15*W15 | Y15: =U15-X15 | Z15: =Y15 | AA15: 11 | AB15: =R15 | AC15: =AJ14 | AD15: 0 | AE15: =AC15+AD15 | AF15: =L15 | AG15: 0.15 | AH15: =AG15*AF15 | AI15: =AE15-AH15 | AJ15: =AI15 | AK15: =Z15+AJ15 | AM15: 11 | AN15: =AB15 | AO15: =AV14 | AP15: 0 | AQ15: =AO15+AP15 | AR15: =K15 | AS15: 0.02 | AT15: =AR15*AS15 | AU15: =AQ15-AT15 | AV15: =AU15 | AW15: 11 | AX15: =AN15 | AY15: =BF14 | AZ15: 0 | BA15: =AY15+AZ15 | BB15: =L15 | BC15: 0.03 | BD15: =BC15*BB15 | BE15: =BA15-BD15 | BF15: =BE15 | BG15: =AV15+BF15 | BI15: 11 | BJ15: =AX15 | BK15: =BR14 | BL15: 0 | BM15: =BK15+BL15 | BN15: 0 | BO15: 0.02 | BP15: =BN15*BO15 | BQ15: =BM15-BP15 | BR15: =BQ15 | BS15: 11 | BT15: =BJ15 | BU15: =CB14 | BV15: 0 | BW15: =BU15+BV15 | BX15: 0 | BY15: 0.03 | BZ15: =BY15*BX15 | CA15: =BW15-BZ15 | CB15: =CA15 | CC15: =BR15+CB15 | CE15: 11 | CF15: =BT15 | CG15: =CN14 | CH15: 0 | CI15: =CG15+CH15 | CJ15: 0 | CK15: 0.02 | CL15: =CJ15*CK15 | CM15: =CI15-CL15 | CN15: =CM15 | CO15: 11 | CP15: =CF15 | CQ15: =CX14 | CR15: 0 | CS15: =CQ15+CR15 | CT15: 0 | CU15: 0.03 | CV15: =CU15*CT15 | CW15: =CS15-CV15 | CX15: =CW15 | CY15: =CN15+CX15 | DA15: 11 | DB15: =CP15 | DC15: =DJ14 | DD15: 0 | DE15: =DC15+DD15 | DF15: =K15 | DG15: 0.0001 | DH15: =DF15*DG15 | DI15: =DE15-DH15 | DJ15: =DI15 | DK15: 11 | DL15: =DB15 | DM15: =DT14 | DN15: 0 | DO15: =DM15+DN15 | DP15: =L15 | DQ15: 0.0003 | DR15: =DQ15*DP15 | DS15: =DO15-DR15 | DT15: =DS15 | DU15: =DJ15+DT15 | DW15: 11 | DX15: =DL15 | DY15: =EF14 | DZ15: 0 | EA15: =DY15+DZ15 | EB15: =K15 | EC15: 0.0002 | ED15: =EB15*EC15 | EE15: =EA15-ED15 | EF15: =EE15 | EG15: 11 | EH15: =DX15 | EI15: =EP14 | EJ15: 0 | EK15: =EI15+EJ15 | EL15: =L15 | EM15: 0.0006 | EN15: =EM15*EL15 | EO15: =EK15-EN15 | EP15: =EO15 | EQ15: =EF15+EP15 | ES15: 11 | ET15: =EH15 | EU15: =FB14 | EV15: 0 | EW15: =EU15+EV15 | EX15: =K15 | EY15: 0.002 | EZ15: =EX15*EY15 | FA15: =EW15-EZ15 | FB15: =FA15 | FC15: 11 | FD15: =ET15 | FE15: =FL14 | FF15: 0 | FG15: =FE15+FF15 | FH15: =L15 | FI15: 0.0025 | FJ15: =FI15*FH15 | FK15: =FG15-FJ15 | FL15: =FK15 | FM15: =FB15+FL15 | FO15: 11 | FP15: =FD15 | FQ15: =FX14 | FR15: 0 | FS15: =FQ15+FR15 | FT15: =K15 | FU15: 0.002 | FV15: =FT15*FU15 | FW15: =FS15-FV15 | FX15: =FW15 | FY15: 11 | FZ15: =FP15 | GA15: =GH14 | GB15: 0 | GC15: =GA15+GB15 | GD15: =L15 | GE15: 0.005 | GF15: =GE15*GD15 | GG15: =GC15-GF15 | GH15: =GG15 | GI15: =FX15+GH15 | GK15: 11 | GL15: =FZ15 | GM15: =GT14 | GN15: 0 | GO15: =GM15+GN15 | GP15: =K15 | GQ15: 0.005 | GR15: =GP15*GQ15 | GS15: =GO15-GR15 | GT15: =GS15 | GU15: 11 | GV15: =GL15 | GW15: =HD14 | GX15: 0 | GY15: =GW15+GX15 | GZ15: =L15 | HA15: 0.0075 | HB15: =HA15*GZ15 | HC15: =GY15-HB15 | HD15: =HC15 | HE15: =GT15+HD15 | HG15: 11 | HH15: =GV15 | HI15: =K15 | HJ15: 1 | HK15: =HI15*HJ15 | HL15: 0.89 | HM15: =HI15*HL15 | HN15: 0.7 | HO15: =HN15*HI15 | HP15: 2.59 | HQ15: =HI15*HP15 | HR15: 11 | HS15: 45237 | HT15: =L15 | HU15: 1.64 | HV15: =HT15*HU15 | HW15: 1.14 | HX15: =HT15*HW15 | HY15: 1.1 | HZ15: =HY15*HT15 | IA15: 3.11 | IB15: =HT15*IA15 | IC15: =HK15+HV15 | ID15: =HM15+HX15 | IE15: =HO15+HZ15 | IG15: =HH15 | IH15: jfookj | IJ15: =IJ14 | IK15: =IJ15 | IL15: =K15 | IM15: =IL15*100 | IN15: =IL15*20 | IQ15: =IL15*0.3 | IR15: =IL15*0.4 | IS15: =IL15*1.5 | IT15: =IL15*5 | IU15: =IL15*2 | IV15: =IL15*2.08 | IX15: =IL15*2.08 | IZ15: =IG15 | JA15: jfookj | JC15: =JC14 | JD15: =JC15 | JE15: =L15 | JF15: =JE15*150 | JG15: =JE15*30 | JJ15: =JE15*0.25 | JK15: =JE15*0.4 | JL15: =JE15*2.5 | JM15: =JE15*7.5 | JN15: =JE15*4 | JO15: =JE15*3.11 | JQ15: =JE15*3.11 | JT15: 9 | JU15: ehB | JV15: =FX35 | JW15: =GH35 | JX15: =SUM(JV15:JW15) | JZ15: 1 | KA15: 9 | KB15: ehB | KC15: =JV15 | KD15: =FR36 | KE15: =FV36 | KG15: =JW15 | KH15: =GB36 | KI15: =GF36
A16: jfookj | B16: 12/04/2026 | C16: 0 | D16: =C16 | E16: 0 | F16: 0 | G16: 0 | H16: =G16+F16+E16 | I16: jfookj | J16: 12/04/2026 | K16: =D16 | L16: =H16 | M16: =SUM(K16:L16) | Q16: 12 | R16: 12/04/2026 | S16: =Z15 | T16: 0 | U16: =S16+T16 | V16: =K16 | W16: 0.1 | X16: =V16*W16 | Y16: =U16-X16 | Z16: =Y16 | AA16: 12 | AB16: =R16 | AC16: =AJ15 | AD16: 0 | AE16: =AC16+AD16 | AF16: =L16 | AG16: 0.15 | AH16: =AG16*AF16 | AI16: =AE16-AH16 | AJ16: =AI16 | AK16: =Z16+AJ16 | AM16: 12 | AN16: =AB16 | AO16: =AV15 | AP16: 0 | AQ16: =AO16+AP16 | AR16: 0 | AS16: 0.02 | AT16: =AR16*AS16 | AU16: =AQ16-AT16 | AV16: =AU16 | AW16: 12 | AX16: =AN16 | AY16: =BF15 | AZ16: 0 | BA16: =AY16+AZ16 | BB16: 0 | BC16: 0.03 | BD16: =BC16*BB16 | BE16: =BA16-BD16 | BF16: =BE16 | BG16: =AV16+BF16 | BI16: 12 | BJ16: =AX16 | BK16: =BR15 | BL16: 0 | BM16: =BK16+BL16 | BN16: 0 | BO16: 0.02 | BP16: =BN16*BO16 | BQ16: =BM16-BP16 | BR16: =BQ16 | BS16: 12 | BT16: =BJ16 | BU16: =CB15 | BV16: 0 | BW16: =BU16+BV16 | BX16: 0 | BY16: 0.03 | BZ16: =BY16*BX16 | CA16: =BW16-BZ16 | CB16: =CA16 | CC16: =BR16+CB16 | CE16: 12 | CF16: =BT16 | CG16: =CN15 | CH16: 0 | CI16: =CG16+CH16 | CJ16: 0 | CK16: 0.02 | CL16: =CJ16*CK16 | CM16: =CI16-CL16 | CN16: =CM16 | CO16: 12 | CP16: =CF16 | CQ16: =CX15 | CR16: 0 | CS16: =CQ16+CR16 | CT16: 0 | CU16: 0.03 | CV16: =CU16*CT16 | CW16: =CS16-CV16 | CX16: =CW16 | CY16: =CN16+CX16 | DA16: 12 | DB16: =CP16 | DC16: =DJ15 | DD16: 0 | DE16: =DC16+DD16 | DF16: =K16 | DG16: 0.0001 | DH16: =DF16*DG16 | DI16: =DE16-DH16 | DJ16: =DI16 | DK16: 12 | DL16: =DB16 | DM16: =DT15 | DN16: 0 | DO16: =DM16+DN16 | DP16: =L16 | DQ16: 0.0003 | DR16: =DQ16*DP16 | DS16: =DO16-DR16 | DT16: =DS16 | DU16: =DJ16+DT16 | DW16: 12 | DX16: =DL16 | DY16: =EF15 | DZ16: 0 | EA16: =DY16+DZ16 | EB16: =K16 | EC16: 0.0002 | ED16: =EB16*EC16 | EE16: =EA16-ED16 | EF16: =EE16 | EG16: 12 | EH16: =DX16 | EI16: =EP15 | EJ16: 0 | EK16: =EI16+EJ16 | EL16: =L16 | EM16: 0.0006 | EN16: =EM16*EL16 | EO16: =EK16-EN16 | EP16: =EO16 | EQ16: =EF16+EP16 | ES16: 12 | ET16: =EH16 | EU16: =FB15 | EV16: 0 | EW16: =EU16+EV16 | EX16: =K16 | EY16: 0.002 | EZ16: =EX16*EY16 | FA16: =EW16-EZ16 | FB16: =FA16 | FC16: 12 | FD16: =ET16 | FE16: =FL15 | FF16: 0 | FG16: =FE16+FF16 | FH16: =L16 | FI16: 0.0025 | FJ16: =FI16*FH16 | FK16: =FG16-FJ16 | FL16: =FK16 | FM16: =FB16+FL16 | FO16: 12 | FP16: =FD16 | FQ16: =FX15 | FR16: 0 | FS16: =FQ16+FR16 | FT16: =K16 | FU16: 0.002 | FV16: =FT16*FU16 | FW16: =FS16-FV16 | FX16: =FW16 | FY16: 12 | FZ16: =FP16 | GA16: =GH15 | GB16: 0 | GC16: =GA16+GB16 | GD16: =L16 | GE16: 0.005 | GF16: =GE16*GD16 | GG16: =GC16-GF16 | GH16: =GG16 | GI16: =FX16+GH16 | GK16: 12 | GL16: =FZ16 | GM16: =GT15 | GN16: 0 | GO16: =GM16+GN16 | GP16: =K16 | GQ16: 0.005 | GR16: =GP16*GQ16 | GS16: =GO16-GR16 | GT16: =GS16 | GU16: 12 | GV16: =GL16 | GW16: =HD15 | GX16: 0 | GY16: =GW16+GX16 | GZ16: =L16 | HA16: 0.0075 | HB16: =HA16*GZ16 | HC16: =GY16-HB16 | HD16: =HC16 | HE16: =GT16+HD16 | HG16: 12 | HH16: =GV16 | HI16: =K16 | HJ16: 1 | HK16: =HI16*HJ16 | HL16: 0.89 | HM16: =HI16*HL16 | HN16: 0.7 | HO16: =HN16*HI16 | HP16: 2.59 | HQ16: =HI16*HP16 | HR16: 12 | HS16: 45267 | HT16: =L16 | HU16: 1.64 | HV16: =HT16*HU16 | HW16: 1.14 | HX16: =HT16*HW16 | HY16: 1.1 | HZ16: =HY16*HT16 | IA16: 3.11 | IB16: =HT16*IA16 | IC16: =HK16+HV16 | ID16: =HM16+HX16 | IE16: =HO16+HZ16 | IG16: =HH16 | IH16: lkseokj | II16: elqj nkG | IJ16: =IJ15 | IK16: =IJ16 | IL16: =K16 | IM16: =IL16*100 | IN16: =IL16*20 | IQ16: =IL16*0.3 | IR16: =IL16*0.4 | IS16: =IL16*1.5 | IT16: =IL16*5 | IU16: =IL16*2 | IV16: =IL16*2.08 | IX16: =IL16*2.08 | IZ16: =IG16 | JA16: lkseokj | JB16: elqj nkG | JC16: =JC15 | JD16: =JC16 | JE16: =L16 | JF16: =JE16*150 | JG16: =JE16*30 | JJ16: =JE16*0.25 | JK16: =JE16*0.4 | JL16: =JE16*2.5 | JM16: =JE16*7.5 | JN16: =JE16*4 | JO16: =JE16*3.11 | JQ16: =JE16*3.11 | JT16: 10 | JU16: lks;k- rsy | JV16: =GT35 | JW16: =HD35 | JX16: =SUM(JV16:JW16) | KA16: 10 | KB16: lks;k- rsy | KC16: =JV16 | KD16: =GN36 | KE16: =GR36 | KG16: =JW16 | KH16: =GX36 | KI16: =HB36
A17: lkseokj | B17: 13/04/2026 | C17: 0 | D17: =C17 | E17: 0 | F17: 0 | G17: 0 | H17: =G17+F17+E17 | I17: lkseokj | J17: 13/04/2026 | K17: =D17 | L17: =H17 | M17: =SUM(K17:L17) | N17: elqj nkG | Q17: 13 | R17: 13/04/2026 | S17: =Z16 | T17: 0 | U17: =S17+T17 | V17: =K17 | W17: 0.1 | X17: =V17*W17 | Y17: =U17-X17 | Z17: =Y17 | AA17: 13 | AB17: =R17 | AC17: =AJ16 | AD17: 0 | AE17: =AC17+AD17 | AF17: =L17 | AG17: 0.15 | AH17: =AG17*AF17 | AI17: =AE17-AH17 | AJ17: =AI17 | AK17: =Z17+AJ17 | AM17: 13 | AN17: =AB17 | AO17: =AV16 | AP17: 0 | AQ17: =AO17+AP17 | AR17: 0 | AS17: 0.02 | AT17: =AR17*AS17 | AU17: =AQ17-AT17 | AV17: =AU17 | AW17: 13 | AX17: =AN17 | AY17: =BF16 | AZ17: 0 | BA17: =AY17+AZ17 | BB17: 0 | BC17: 0.03 | BD17: =BC17*BB17 | BE17: =BA17-BD17 | BF17: =BE17 | BG17: =AV17+BF17 | BI17: 13 | BJ17: =AX17 | BK17: =BR16 | BL17: 0 | BM17: =BK17+BL17 | BN17: =K17 | BO17: 0.02 | BP17: =BN17*BO17 | BQ17: =BM17-BP17 | BR17: =BQ17 | BS17: 13 | BT17: =BJ17 | BU17: =CB16 | BV17: 0 | BW17: =BU17+BV17 | BX17: =L17 | BY17: 0.03 | BZ17: =BY17*BX17 | CA17: =BW17-BZ17 | CB17: =CA17 | CC17: =BR17+CB17 | CE17: 13 | CF17: =BT17 | CG17: =CN16 | CH17: 0 | CI17: =CG17+CH17 | CJ17: 0 | CK17: 0.02 | CL17: =CJ17*CK17 | CM17: =CI17-CL17 | CN17: =CM17 | CO17: 13 | CP17: =CF17 | CQ17: =CX16 | CR17: 0 | CS17: =CQ17+CR17 | CT17: 0 | CU17: 0.03 | CV17: =CU17*CT17 | CW17: =CS17-CV17 | CX17: =CW17 | CY17: =CN17+CX17 | DA17: 13 | DB17: =CP17 | DC17: =DJ16 | DD17: 0 | DE17: =DC17+DD17 | DF17: =K17 | DG17: 0.0001 | DH17: =DF17*DG17 | DI17: =DE17-DH17 | DJ17: =DI17 | DK17: 13 | DL17: =DB17 | DM17: =DT16 | DN17: 0 | DO17: =DM17+DN17 | DP17: =L17 | DQ17: 0.0003 | DR17: =DQ17*DP17 | DS17: =DO17-DR17 | DT17: =DS17 | DU17: =DJ17+DT17 | DW17: 13 | DX17: =DL17 | DY17: =EF16 | DZ17: 0 | EA17: =DY17+DZ17 | EB17: =K17 | EC17: 0.0002 | ED17: =EB17*EC17 | EE17: =EA17-ED17 | EF17: =EE17 | EG17: 13 | EH17: =DX17 | EI17: =EP16 | EJ17: 0 | EK17: =EI17+EJ17 | EL17: =L17 | EM17: 0.0006 | EN17: =EM17*EL17 | EO17: =EK17-EN17 | EP17: =EO17 | EQ17: =EF17+EP17 | ES17: 13 | ET17: =EH17 | EU17: =FB16 | EV17: 0 | EW17: =EU17+EV17 | EX17: =K17 | EY17: 0.002 | EZ17: =EX17*EY17 | FA17: =EW17-EZ17 | FB17: =FA17 | FC17: 13 | FD17: =ET17 | FE17: =FL16 | FF17: 0 | FG17: =FE17+FF17 | FH17: =L17 | FI17: 0.0025 | FJ17: =FI17*FH17 | FK17: =FG17-FJ17 | FL17: =FK17 | FM17: =FB17+FL17 | FO17: 13 | FP17: =FD17 | FQ17: =FX16 | FR17: 0 | FS17: =FQ17+FR17 | FT17: =K17 | FU17: 0.002 | FV17: =FT17*FU17 | FW17: =FS17-FV17 | FX17: =FW17 | FY17: 13 | FZ17: =FP17 | GA17: =GH16 | GB17: 0 | GC17: =GA17+GB17 | GD17: =L17 | GE17: 0.005 | GF17: =GE17*GD17 | GG17: =GC17-GF17 | GH17: =GG17 | GI17: =FX17+GH17 | GK17: 13 | GL17: =FZ17 | GM17: =GT16 | GN17: 0 | GO17: =GM17+GN17 | GP17: =K17 | GQ17: 0.005 | GR17: =GP17*GQ17 | GS17: =GO17-GR17 | GT17: =GS17 | GU17: 13 | GV17: =GL17 | GW17: =HD16 | GX17: 0 | GY17: =GW17+GX17 | GZ17: =L17 | HA17: 0.0075 | HB17: =HA17*GZ17 | HC17: =GY17-HB17 | HD17: =HC17 | HE17: =GT17+HD17 | HG17: 13 | HH17: =GV17 | HI17: =K17 | HJ17: 1 | HK17: =HI17*HJ17 | HL17: 0.89 | HM17: =HI17*HL17 | HN17: 0.7 | HO17: =HN17*HI17 | HP17: 2.59 | HQ17: =HI17*HP17 | HR17: 13 | HS17: 13/7/2023 | HT17: =L17 | HU17: 1.64 | HV17: =HT17*HU17 | HW17: 1.14 | HX17: =HT17*HW17 | HY17: 1.1 | HZ17: =HY17*HT17 | IA17: 3.11 | IB17: =HT17*IA17 | IC17: =HK17+HV17 | ID17: =HM17+HX17 | IE17: =HO17+HZ17 | IG17: =HH17 | IH17: eaxGokj | II17: okVk.kk | IJ17: =IJ16 | IK17: =IJ17 | IL17: =K17 | IM17: =IL17*100 | IO17: =IL17*20 | IQ17: =IL17*0.3 | IR17: =IL17*0.4 | IS17: =IL17*1.5 | IT17: =IL17*5 | IU17: =IL17*2 | IV17: =IL17*2.08 | IX17: =IL17*2.08 | IZ17: =IG17 | JA17: eaxGokj | JB17: okVk.kk | JC17: =JC16 | JD17: =JC17 | JE17: =L17 | JF17: =JE17*150 | JH17: =JE17*30 | JJ17: =JE17*0.25 | JK17: =JE17*0.4 | JL17: =JE17*2.5 | JM17: =JE17*7.5 | JN17: =JE17*4 | JO17: =JE17*3.11 | JQ17: =JE17*3.11 | JT17: 10 | KA17: 10
